Workbook
Name _1J_INV_INC_REIN_AC____?0?˜?“0000____?0?˜?“0000?_?”?_?“?“__?“?0?”00000: #REF!
Name AFFCOMM_ALIEN_DIFF: #REF!
Name AFFCOMM_ALIEN_STMT_TOT_COMM: #REF!
Name AFFCOMM_ALIEN_TOT_REP: #REF!
Name AFFCOMM_ASCII_DATA: #REF!
Name AFFCOMM_ASCII_FORMAT: #REF!
Name AFFCOMM_INV_SUB_DIFF: #REF!
Name AFFCOMM_INV_SUB_STMT_TOT_COMM: #REF!
Name AFFCOMM_INV_SUB_TOT_REP: #REF!
Name AFFCOMM_LIFE_DIFF: #REF!
Name AFFCOMM_LIFE_STMT_TOT_COMM: #REF!
Name AFFCOMM_LIFE_TOT_REP: #REF!
Name AFFCOMM_NON_INS_DIFF: #REF!
Name AFFCOMM_NON_INS_STMT_TOT_COMM: #REF!
Name AFFCOMM_NON_INS_TOT_REP: #REF!
Name AFFCOMM_OTH_AFFIL_DIFF: #REF!
Name AFFCOMM_OTH_AFFIL_STMT_TOT_COMM: #REF!
Name AFFCOMM_OTH_AFFIL_TOT_REP: #REF!
Name AFFCOMM_PARENT_DIFF: #REF!
Name AFFCOMM_PARENT_STMT_TOT: #REF!
Name AFFCOMM_PARENT_TOT_REP: #REF!
Name AFFCOMM_PC_DIFF: #REF!
Name AFFCOMM_PC_STMT_TOT_COMM: #REF!
Name AFFCOMM_PC_TOT_REP: #REF!
Name AFFCOMM_SUBTOT_DIFF: #REF!
Name AFFCOMM_SUBTOT_STMT_TOT_COMM: #REF!
Name AFFCOMM_SUBTOT_TOT_REP: #REF!
Name AFFPREF_AFFIL_BOND_DIFF: #REF!
Name AFFPREF_AFFIL_BOND_STMT_TOT_PREF: #REF!
Name AFFPREF_AFFIL_BOND_TOT_REP: #REF!
Name AFFPREF_ALIEN_INS_DIFF: #REF!
Name AFFPREF_ALIEN_INS_STMT_TOT_PREF: #REF!
Name AFFPREF_ALIEN_INS_TOT_REP: #REF!
Name AFFPREF_ASCII_DATA: #REF!
Name AFFPREF_ASCII_FORMAT: #REF!
Name AFFPREF_INV_SUB_DIFF: #REF!
Name AFFPREF_INV_SUB_STMT_TOT_PREF: #REF!
Name AFFPREF_INV_SUB_TOT_REP: #REF!
Name AFFPREF_LIFE_DIFF: #REF!
Name AFFPREF_LIFE_STMT_TOT_PREF: #REF!
Name AFFPREF_LIFE_TOT_REP: #REF!
Name AFFPREF_NON_INS_DIFF: #REF!
Name AFFPREF_NON_INS_STMT_TOT_PREF: #REF!
Name AFFPREF_NON_INS_TOT_REP: #REF!
Name AFFPREF_OTH_AFFIL_DIFF: #REF!
Name AFFPREF_OTH_AFFIL_STMT_TOT_PREF: #REF!
Name AFFPREF_OTH_AFFIL_TOT_REP: #REF!
Name AFFPREF_PARENT_DIFF: #REF!
Name AFFPREF_PARENT_STMT_TOT_PREF: #REF!
Name AFFPREF_PARENT_TOT_REP: #REF!
Name AFFPREF_PC_DIFF: #REF!
Name AFFPREF_PC_STMT_TOT_PREF: #REF!
Name AFFPREF_PC_TOT_REP: #REF!
Name AFFPREF_SUBTOT_DIFF: #REF!
Name AFFPREF_SUBTOT_STMT_TOT_PREF: #REF!
Name AFFPREF_SUBTOT_TOT_REP: #REF!
Name AFFSUM_ASCII_DATA: #REF!
Name AFFSUM_ASCII_FORMAT: #REF!
Name AFFSUM_DIR_LIFE_REQ: #REF!
Name AFFSUM_DIR_LIFE_REQ_AFFIL_PREF: #REF!

Sheet Bilanço
B3: =E3 -> TOPLAM (HAYAT DIŞI ŞİRKETLER+HAYAT VE EMEKLİLİK ŞİRKETLERİ+REASÜRANS ŞİRKETLERİ) | E3: TOPLAM (HAYAT DIŞI ŞİRKETLER+HAYAT VE EMEKLİLİK ŞİRKETLERİ+REASÜRANS ŞİRKETLERİ) | H3: Lütfen Seçimlerinizi Yapınız | BC3: Chubb European Group SE Merkezi Fransa Türkiye İstanbul Şubesi | BD3: 1001
B4: Aktif - Haziran 2026 | E4: Pasif - Haziran 2026 | BC4: Aksigorta AŞ | BD4: 1003
BC5: Allianz Sigorta AŞ | BD5: 1004
B6: I. CARİ VARLIKLAR | C6: =+C7+C14+C23+C34+C44+C52+C57 -> 2.2452939e+12 | E6: III- KISA VADELİ YÜKÜMLÜLÜKLER | F6: =+F7+F16+F23+F30+F35+F42+F50+F54+F58 -> 1.6544712e+12 | BC6: Anadolu Anonim Türk Sigorta Şirketi | BD6: 1005
B7: A. Nakit ve Nakit Benzeri Varlıklar | C7: =SUM(C8:C13) -> 5.850349e+11 | E7: A- Finansal Borçlar | F7: =SUM(F8:F15) -> 2.3480174e+10 | BC7: Ankara Anonim Türk Sigorta Şirketi | BD7: 1006
A8: 100 | B8: 1- Kasa | C8: =INDIRECT("'Aktif Detay'!"&ADDRESS(IFERROR(MATCH(VLOOKUP($E$3,$BC$3:$BE$140,2,0),'Aktif Detay'!$B:$B,0),MATCH(9003,'Aktif Detay'!$B:$B,0)+1),MATCH(A8,'Aktif Detay'!$5:$5,0))) -> 5585763.2 | D8: 300 | E8: 1- Kredi Kuruluşlarına Borçlar | F8: =INDIRECT("'Pasif Detay'!"&ADDRESS(IFERROR(MATCH(VLOOKUP($E$3,$BC$3:$BE$140,2,0),'Pasif Detay'!$B:$B,0),MATCH(9003,'Pasif Detay'!$B:$B,0)+1),MATCH(D8,'Pasif Detay'!$5:$5,0))) -> 4760868.2 | BC8: Atradius Crédito y Caución S.A. de Seguros y Reaseguros, İstanbul Şubesi | BD8: 1007
A9: 101 | B9: 2- Alınan Çekler | C9: =INDIRECT("'Aktif Detay'!"&ADDRESS(IFERROR(MATCH(VLOOKUP($E$3,$BC$3:$BE$140,2,0),'Aktif Detay'!$B:$B,0),MATCH(9003,'Aktif Detay'!$B:$B,0)+1),MATCH(A9,'Aktif Detay'!$5:$5,0))) -> 35070126 | D9: 301 | E9: 2- Finansal Kiralama İşlemlerinden Borçlar | F9: =INDIRECT("'Pasif Detay'!"&ADDRESS(IFERROR(MATCH(VLOOKUP($E$3,$BC$3:$BE$140,2,0),'Pasif Detay'!$B:$B,0),MATCH(9003,'Pasif Detay'!$B:$B,0)+1),MATCH(D9,'Pasif Detay'!$5:$5,0))) -> 2.1830306e+09 | BC9: Unico Sigorta AŞ | BD9: 1008
A10: 102 | B10: 3- Bankalar; | C10: =INDIRECT("'Aktif Detay'!"&ADDRESS(IFERROR(MATCH(VLOOKUP($E$3,$BC$3:$BE$140,2,0),'Aktif Detay'!$B:$B,0),MATCH(9003,'Aktif Detay'!$B:$B,0)+1),MATCH(A10,'Aktif Detay'!$5:$5,0))) -> 4.67103e+11 | D10: 302 | E10: 3- Ertelenmiş Finansal Kiralama Borçlanma Maliyetleri | F10: =INDIRECT("'Pasif Detay'!"&ADDRESS(IFERROR(MATCH(VLOOKUP($E$3,$BC$3:$BE$140,2,0),'Pasif Detay'!$B:$B,0),MATCH(9003,'Pasif Detay'!$B:$B,0)+1),MATCH(D10,'Pasif Detay'!$5:$5,0))) -> -5.3136759e+08 | BC10: Axa Sigorta AŞ | BD10: 1009
A11: 103 | B11: 4- Verilen Çekler Ve Ödeme Emirleri (-) | C11: =INDIRECT("'Aktif Detay'!"&ADDRESS(IFERROR(MATCH(VLOOKUP($E$3,$BC$3:$BE$140,2,0),'Aktif Detay'!$B:$B,0),MATCH(9003,'Aktif Detay'!$B:$B,0)+1),MATCH(A11,'Aktif Detay'!$5:$5,0))) -> -6310.97 | D11: 303 | E11: 4- Uzun Vadeli Kredilerin Ana Para Taksitleri Ve Faizleri | F11: =INDIRECT("'Pasif Detay'!"&ADDRESS(IFERROR(MATCH(VLOOKUP($E$3,$BC$3:$BE$140,2,0),'Pasif Detay'!$B:$B,0),MATCH(9003,'Pasif Detay'!$B:$B,0)+1),MATCH(D11,'Pasif Detay'!$5:$5,0))) -> 0 | BC11: BNP Paribas Cardif Sigorta AŞ | BD11: 1010
A12: 106 | B12: 5- Banka Garantili ve 3 Aydan Kısa Vadeli | C12: =INDIRECT("'Aktif Detay'!"&ADDRESS(IFERROR(MATCH(VLOOKUP($E$3,$BC$3:$BE$140,2,0),'Aktif Detay'!$B:$B,0),MATCH(9003,'Aktif Detay'!$B:$B,0)+1),MATCH(A12,'Aktif Detay'!$5:$5,0))) -> 1.148111e+11 | D12: 304 | E12: 5- Çıkarılmış Tahviller(Bonolar) Anapara, Taksit ve Faizleri | F12: =INDIRECT("'Pasif Detay'!"&ADDRESS(IFERROR(MATCH(VLOOKUP($E$3,$BC$3:$BE$140,2,0),'Pasif Detay'!$B:$B,0),MATCH(9003,'Pasif Detay'!$B:$B,0)+1),MATCH(D12,'Pasif Detay'!$5:$5,0))) -> 0 | BC12: Coface Sigorta AŞ | BD12: 1011
A13: 109 | B13: 6- Diğer Nakit Ve Nakit Benzeri Varlıklar | C13: =INDIRECT("'Aktif Detay'!"&ADDRESS(IFERROR(MATCH(VLOOKUP($E$3,$BC$3:$BE$140,2,0),'Aktif Detay'!$B:$B,0),MATCH(9003,'Aktif Detay'!$B:$B,0)+1),MATCH(A13,'Aktif Detay'!$5:$5,0))) -> 3.0801448e+09 | D13: 307 | E13: 6- Çıkarılmış Diğer Finansal Varlıklar | F13: =INDIRECT("'Pasif Detay'!"&ADDRESS(IFERROR(MATCH(VLOOKUP($E$3,$BC$3:$BE$140,2,0),'Pasif Detay'!$B:$B,0),MATCH(9003,'Pasif Detay'!$B:$B,0)+1),MATCH(D13,'Pasif Detay'!$5:$5,0))) -> 0 | BC13: Corpus Sigorta AŞ | BD13: 1012
B14: B. Finansal Varlıklar ile Riski Sigortalılara Ait Fin. Yat. | C14: =SUM(C15:C22) -> 8.0241602e+11 | D14: 308 | E14: 7- Çıkarılmış Diğer Finansal Varlıklar İhraç Farkı | F14: =INDIRECT("'Pasif Detay'!"&ADDRESS(IFERROR(MATCH(VLOOKUP($E$3,$BC$3:$BE$140,2,0),'Pasif Detay'!$B:$B,0),MATCH(9003,'Pasif Detay'!$B:$B,0)+1),MATCH(D14,'Pasif Detay'!$5:$5,0))) -> 0 | BC14: VHV Allgemeine Sigorta AŞ | BD14: 1013
A15: 110 | B15: 1- Satılmaya Hazır Finansal Varlıklar | C15: =INDIRECT("'Aktif Detay'!"&ADDRESS(IFERROR(MATCH(VLOOKUP($E$3,$BC$3:$BE$140,2,0),'Aktif Detay'!$B:$B,0),MATCH(9003,'Aktif Detay'!$B:$B,0)+1),MATCH(A15,'Aktif Detay'!$5:$5,0))) -> 3.3222796e+11 | D15: 309 | E15: 8- Diğer Finansal Borçlar (Yükümlülükler) | F15: =INDIRECT("'Pasif Detay'!"&ADDRESS(IFERROR(MATCH(VLOOKUP($E$3,$BC$3:$BE$140,2,0),'Pasif Detay'!$B:$B,0),MATCH(9003,'Pasif Detay'!$B:$B,0)+1),MATCH(D15,'Pasif Detay'!$5:$5,0))) -> 2.182375e+10 | BC15: Euler Hermes Sigorta AŞ | BD15: 1016
A16: 111 | B16: 2- Vadeye Kadar Elde Tutulacak Finansal Varlıklar | C16: =INDIRECT("'Aktif Detay'!"&ADDRESS(IFERROR(MATCH(VLOOKUP($E$3,$BC$3:$BE$140,2,0),'Aktif Detay'!$B:$B,0),MATCH(9003,'Aktif Detay'!$B:$B,0)+1),MATCH(A16,'Aktif Detay'!$5:$5,0))) -> 6.9567248e+10 | E16: B- Esas Faaliyetlerden Borçlar | F16: =SUM(F17:F22) -> 5.3693255e+11 | BC16: Eureko Sigorta AŞ | BD16: 1017
A17: 112 | B17: 3- Alım Satım Amaçlı Finansal Varlıklar | C17: =INDIRECT("'Aktif Detay'!"&ADDRESS(IFERROR(MATCH(VLOOKUP($E$3,$BC$3:$BE$140,2,0),'Aktif Detay'!$B:$B,0),MATCH(9003,'Aktif Detay'!$B:$B,0)+1),MATCH(A17,'Aktif Detay'!$5:$5,0))) -> 2.7089864e+11 | D17: 320 | E17: 1- Sigortacılık Faaliyetlerinden Borçlar | F17: =INDIRECT("'Pasif Detay'!"&ADDRESS(IFERROR(MATCH(VLOOKUP($E$3,$BC$3:$BE$140,2,0),'Pasif Detay'!$B:$B,0),MATCH(9003,'Pasif Detay'!$B:$B,0)+1),MATCH(D17,'Pasif Detay'!$5:$5,0))) -> 9.3435552e+10 | BC17: Referans Sigorta AŞ | BD17: 1018
A18: 115 | B18: 4- Krediler | C18: =INDIRECT("'Aktif Detay'!"&ADDRESS(IFERROR(MATCH(VLOOKUP($E$3,$BC$3:$BE$140,2,0),'Aktif Detay'!$B:$B,0),MATCH(9003,'Aktif Detay'!$B:$B,0)+1),MATCH(A18,'Aktif Detay'!$5:$5,0))) -> 1.5446905e+09 | D18: 322 | E18: 2- Reasürans Faaliyetlerinden Borçlar | F18: =INDIRECT("'Pasif Detay'!"&ADDRESS(IFERROR(MATCH(VLOOKUP($E$3,$BC$3:$BE$140,2,0),'Pasif Detay'!$B:$B,0),MATCH(9003,'Pasif Detay'!$B:$B,0)+1),MATCH(D18,'Pasif Detay'!$5:$5,0))) -> 3.833029e+09 | BC18: Türkiye Sigorta AŞ | BD18: 1020
A19: 116 | B19: 5- Krediler Karşılığı (-) | C19: =INDIRECT("'Aktif Detay'!"&ADDRESS(IFERROR(MATCH(VLOOKUP($E$3,$BC$3:$BE$140,2,0),'Aktif Detay'!$B:$B,0),MATCH(9003,'Aktif Detay'!$B:$B,0)+1),MATCH(A19,'Aktif Detay'!$5:$5,0))) -> 0 | D19: 324 | E19: 3- Sigorta Ve Reasürans Şirketlerinden Alınan Depolar | F19: =INDIRECT("'Pasif Detay'!"&ADDRESS(IFERROR(MATCH(VLOOKUP($E$3,$BC$3:$BE$140,2,0),'Pasif Detay'!$B:$B,0),MATCH(9003,'Pasif Detay'!$B:$B,0)+1),MATCH(D19,'Pasif Detay'!$5:$5,0))) -> 4.0862668e+08 | BC19: HDI Sigorta AŞ | BD19: 1022
A20: 117 | B20: 6- Riski Hayat Poliçesi Sahiplerine Ait Finansal Yatırımlar | C20: =INDIRECT("'Aktif Detay'!"&ADDRESS(IFERROR(MATCH(VLOOKUP($E$3,$BC$3:$BE$140,2,0),'Aktif Detay'!$B:$B,0),MATCH(9003,'Aktif Detay'!$B:$B,0)+1),MATCH(A20,'Aktif Detay'!$5:$5,0))) -> 1.2818281e+11 | D20: 327 | E20: 4- Emeklilik Faaliyetlerinden Borçlar | F20: =INDIRECT("'Pasif Detay'!"&ADDRESS(IFERROR(MATCH(VLOOKUP($E$3,$BC$3:$BE$140,2,0),'Pasif Detay'!$B:$B,0),MATCH(9003,'Pasif Detay'!$B:$B,0)+1),MATCH(D20,'Pasif Detay'!$5:$5,0))) -> 4.2535334e+11 | BC20: Bereket Sigorta AŞ | BD20: 1025
A21: 118 | B21: 7- Şirket Hissesi | C21: =INDIRECT("'Aktif Detay'!"&ADDRESS(IFERROR(MATCH(VLOOKUP($E$3,$BC$3:$BE$140,2,0),'Aktif Detay'!$B:$B,0),MATCH(9003,'Aktif Detay'!$B:$B,0)+1),MATCH(A21,'Aktif Detay'!$5:$5,0))) -> 0 | D21: 328 | E21: 5- Diğer Esas Faaliyetlerden Borçlar | F21: =INDIRECT("'Pasif Detay'!"&ADDRESS(IFERROR(MATCH(VLOOKUP($E$3,$BC$3:$BE$140,2,0),'Pasif Detay'!$B:$B,0),MATCH(9003,'Pasif Detay'!$B:$B,0)+1),MATCH(D21,'Pasif Detay'!$5:$5,0))) -> 1.4481576e+10 | BC21: Magdeburger Sigorta AŞ | BD21: 1027
A22: 119 | B22: 8- Finansal Varlıklar Değer Düşüklüğü Karşılığı (-) | C22: =INDIRECT("'Aktif Detay'!"&ADDRESS(IFERROR(MATCH(VLOOKUP($E$3,$BC$3:$BE$140,2,0),'Aktif Detay'!$B:$B,0),MATCH(9003,'Aktif Detay'!$B:$B,0)+1),MATCH(A22,'Aktif Detay'!$5:$5,0))) -> -5327818 | D22: 329 | E22: 6- Diğer Esas Faaliyetlerden Borçlar Borç Senetleri Reeskontu | F22: =INDIRECT("'Pasif Detay'!"&ADDRESS(IFERROR(MATCH(VLOOKUP($E$3,$BC$3:$BE$140,2,0),'Pasif Detay'!$B:$B,0),MATCH(9003,'Pasif Detay'!$B:$B,0)+1),MATCH(D22,'Pasif Detay'!$5:$5,0))) -> -5.7957799e+08 | BC22: Mapfre Sigorta AŞ | BD22: 1028
B23: C. Esas Faaliyetlerden Alacaklar | C23: =SUM(C24:C33) -> 6.9324991e+11 | E23: C-İlişkili Taraflara Borçlar | F23: =SUM(F24:F29) -> 9.7500907e+09 | BC23: Neova Katılım Sigorta AŞ | BD23: 1030
A24: 120 | B24: 1- Sigortacılık Faaliyetlerinden Alacaklar | C24: =INDIRECT("'Aktif Detay'!"&ADDRESS(IFERROR(MATCH(VLOOKUP($E$3,$BC$3:$BE$140,2,0),'Aktif Detay'!$B:$B,0),MATCH(9003,'Aktif Detay'!$B:$B,0)+1),MATCH(A24,'Aktif Detay'!$5:$5,0))) -> 2.6208064e+11 | D24: 331 | E24: 1- Ortaklara Borçlar | F24: =INDIRECT("'Pasif Detay'!"&ADDRESS(IFERROR(MATCH(VLOOKUP($E$3,$BC$3:$BE$140,2,0),'Pasif Detay'!$B:$B,0),MATCH(9003,'Pasif Detay'!$B:$B,0)+1),MATCH(D24,'Pasif Detay'!$5:$5,0))) -> 8.3644544e+09 | BC24: Orient Sigorta AŞ | BD24: 1031
A25: 121 | B25: 2- Sigortacılık Faaliyetlerinden Alacaklar Karşılığı (-) | C25: =INDIRECT("'Aktif Detay'!"&ADDRESS(IFERROR(MATCH(VLOOKUP($E$3,$BC$3:$BE$140,2,0),'Aktif Detay'!$B:$B,0),MATCH(9003,'Aktif Detay'!$B:$B,0)+1),MATCH(A25,'Aktif Detay'!$5:$5,0))) -> -3.9173953e+09 | D25: 332 | E25: 2- İştiraklere Borçlar | F25: =INDIRECT("'Pasif Detay'!"&ADDRESS(IFERROR(MATCH(VLOOKUP($E$3,$BC$3:$BE$140,2,0),'Pasif Detay'!$B:$B,0),MATCH(9003,'Pasif Detay'!$B:$B,0)+1),MATCH(D25,'Pasif Detay'!$5:$5,0))) -> 0 | BC25: Ray Sigorta AŞ | BD25: 1032
A26: 122 | B26: 3- Reasürans Faaliyetlerinden Alacaklar | C26: =INDIRECT("'Aktif Detay'!"&ADDRESS(IFERROR(MATCH(VLOOKUP($E$3,$BC$3:$BE$140,2,0),'Aktif Detay'!$B:$B,0),MATCH(9003,'Aktif Detay'!$B:$B,0)+1),MATCH(A26,'Aktif Detay'!$5:$5,0))) -> 1.497758e+10 | D26: 333 | E26: 3- Bağlı Ortaklıklara Borçlar | F26: =INDIRECT("'Pasif Detay'!"&ADDRESS(IFERROR(MATCH(VLOOKUP($E$3,$BC$3:$BE$140,2,0),'Pasif Detay'!$B:$B,0),MATCH(9003,'Pasif Detay'!$B:$B,0)+1),MATCH(D26,'Pasif Detay'!$5:$5,0))) -> 4855517 | BC26: Şeker Sigorta AŞ | BD26: 1034
A27: 123 | B27: 4- Reasürans Faaliyetlerinden Alacaklar Karşılığı (-) | C27: =INDIRECT("'Aktif Detay'!"&ADDRESS(IFERROR(MATCH(VLOOKUP($E$3,$BC$3:$BE$140,2,0),'Aktif Detay'!$B:$B,0),MATCH(9003,'Aktif Detay'!$B:$B,0)+1),MATCH(A27,'Aktif Detay'!$5:$5,0))) -> -92718171 | D27: 334 | E27: 4- Müşterek Yönetime Tabi Teşebbüslere Borçlar | F27: =INDIRECT("'Pasif Detay'!"&ADDRESS(IFERROR(MATCH(VLOOKUP($E$3,$BC$3:$BE$140,2,0),'Pasif Detay'!$B:$B,0),MATCH(9003,'Pasif Detay'!$B:$B,0)+1),MATCH(D27,'Pasif Detay'!$5:$5,0))) -> 37681424 | BC27: Sompo Sigorta AŞ | BD27: 1035
A28: 124 | B28: 5- Sigorta Ve Reasürans Şirketleri Nezdindeki Depolar | C28: =INDIRECT("'Aktif Detay'!"&ADDRESS(IFERROR(MATCH(VLOOKUP($E$3,$BC$3:$BE$140,2,0),'Aktif Detay'!$B:$B,0),MATCH(9003,'Aktif Detay'!$B:$B,0)+1),MATCH(A28,'Aktif Detay'!$5:$5,0))) -> 5.9348539e+09 | D28: 335 | E28: 5- Personele Borçlar | F28: =INDIRECT("'Pasif Detay'!"&ADDRESS(IFERROR(MATCH(VLOOKUP($E$3,$BC$3:$BE$140,2,0),'Pasif Detay'!$B:$B,0),MATCH(9003,'Pasif Detay'!$B:$B,0)+1),MATCH(D28,'Pasif Detay'!$5:$5,0))) -> 2.3037036e+08 | BC28: Doga Sigorta AŞ | BD28: 1036
A29: 125 | B29: 6- Sigortalılara Krediler (İkrazlar) | C29: =INDIRECT("'Aktif Detay'!"&ADDRESS(IFERROR(MATCH(VLOOKUP($E$3,$BC$3:$BE$140,2,0),'Aktif Detay'!$B:$B,0),MATCH(9003,'Aktif Detay'!$B:$B,0)+1),MATCH(A29,'Aktif Detay'!$5:$5,0))) -> 4.6638748e+09 | D29: 338 | E29: 6- Diğer İlişkili Taraflara Borçlar | F29: =INDIRECT("'Pasif Detay'!"&ADDRESS(IFERROR(MATCH(VLOOKUP($E$3,$BC$3:$BE$140,2,0),'Pasif Detay'!$B:$B,0),MATCH(9003,'Pasif Detay'!$B:$B,0)+1),MATCH(D29,'Pasif Detay'!$5:$5,0))) -> 1.112729e+09 | BC29: Koru Sigorta AŞ | BD29: 1037
A30: 126 | B30: 7- Sigortalılara Krediler (İkrazlar) Karşılığı (-) | C30: =INDIRECT("'Aktif Detay'!"&ADDRESS(IFERROR(MATCH(VLOOKUP($E$3,$BC$3:$BE$140,2,0),'Aktif Detay'!$B:$B,0),MATCH(9003,'Aktif Detay'!$B:$B,0)+1),MATCH(A30,'Aktif Detay'!$5:$5,0))) -> 0 | E30: D- Diğer Borçlar | F30: =SUM(F31:F34) -> 2.6558512e+10 | BC30: GIG Sigorta AŞ | BD30: 1038
A31: 127 | B31: 8- Emeklilik Faaliyetlerinden Alacaklar | C31: =INDIRECT("'Aktif Detay'!"&ADDRESS(IFERROR(MATCH(VLOOKUP($E$3,$BC$3:$BE$140,2,0),'Aktif Detay'!$B:$B,0),MATCH(9003,'Aktif Detay'!$B:$B,0)+1),MATCH(A31,'Aktif Detay'!$5:$5,0))) -> 4.0940422e+11 | D31: 345 | E31: 1- Alınan Depozito ve Teminatlar | F31: =INDIRECT("'Pasif Detay'!"&ADDRESS(IFERROR(MATCH(VLOOKUP($E$3,$BC$3:$BE$140,2,0),'Pasif Detay'!$B:$B,0),MATCH(9003,'Pasif Detay'!$B:$B,0)+1),MATCH(D31,'Pasif Detay'!$5:$5,0))) -> 1.9020793e+09 | BC31: Türk Nippon Sigorta AŞ | BD31: 1039
A32: 128 | B32: 9- Esas Faaliyetlerden Kaynaklanan Şüpheli Alacaklar | C32: =INDIRECT("'Aktif Detay'!"&ADDRESS(IFERROR(MATCH(VLOOKUP($E$3,$BC$3:$BE$140,2,0),'Aktif Detay'!$B:$B,0),MATCH(9003,'Aktif Detay'!$B:$B,0)+1),MATCH(A32,'Aktif Detay'!$5:$5,0))) -> 2.8340856e+10 | D32: 346 | E32: 2- SGK'ya Borçlar | F32: =INDIRECT("'Pasif Detay'!"&ADDRESS(IFERROR(MATCH(VLOOKUP($E$3,$BC$3:$BE$140,2,0),'Pasif Detay'!$B:$B,0),MATCH(9003,'Pasif Detay'!$B:$B,0)+1),MATCH(D32,'Pasif Detay'!$5:$5,0))) -> 7.614363e+09 | BC32: Türk P&I Sigorta AŞ | BD32: 1040
A33: 129 | B33: 10- Esas Faaliyetlerden Kaynaklanan Şüpheli Alacaklar Karş.(-) | C33: =INDIRECT("'Aktif Detay'!"&ADDRESS(IFERROR(MATCH(VLOOKUP($E$3,$BC$3:$BE$140,2,0),'Aktif Detay'!$B:$B,0),MATCH(9003,'Aktif Detay'!$B:$B,0)+1),MATCH(A33,'Aktif Detay'!$5:$5,0))) -> -2.8142e+10 | D33: 347 | E33: 3- Diğer Çeşitli Borçlar | F33: =INDIRECT("'Pasif Detay'!"&ADDRESS(IFERROR(MATCH(VLOOKUP($E$3,$BC$3:$BE$140,2,0),'Pasif Detay'!$B:$B,0),MATCH(9003,'Pasif Detay'!$B:$B,0)+1),MATCH(D33,'Pasif Detay'!$5:$5,0))) -> 1.7239982e+10 | BC33: Zurich Sigorta AŞ | BD33: 1043
B34: D. İlişkili Taraflardan Alacaklar | C34: =SUM(C35:C43) -> 6.6700859e+08 | D34: 349 | E34: 4- Diğer Çeşitli Borçlar Reeskontu | F34: =INDIRECT("'Pasif Detay'!"&ADDRESS(IFERROR(MATCH(VLOOKUP($E$3,$BC$3:$BE$140,2,0),'Pasif Detay'!$B:$B,0),MATCH(9003,'Pasif Detay'!$B:$B,0)+1),MATCH(D34,'Pasif Detay'!$5:$5,0))) -> -1.9791193e+08 | BC34: Ethica Sigorta AŞ | BD34: 1044
A35: 131 | B35: 1- Ortaklardan Alacaklar | C35: =INDIRECT("'Aktif Detay'!"&ADDRESS(IFERROR(MATCH(VLOOKUP($E$3,$BC$3:$BE$140,2,0),'Aktif Detay'!$B:$B,0),MATCH(9003,'Aktif Detay'!$B:$B,0)+1),MATCH(A35,'Aktif Detay'!$5:$5,0))) -> 47598423 | E35: E-Sigortacılık Teknik Karşılıkları | F35: =SUM(F36:F41) -> 9.8485778e+11 | BC35: Quick Sigorta AŞ | BD35: 1045
A36: 132 | B36: 2- İştiraklerden Alacaklar | C36: =INDIRECT("'Aktif Detay'!"&ADDRESS(IFERROR(MATCH(VLOOKUP($E$3,$BC$3:$BE$140,2,0),'Aktif Detay'!$B:$B,0),MATCH(9003,'Aktif Detay'!$B:$B,0)+1),MATCH(A36,'Aktif Detay'!$5:$5,0))) -> 2.2090569e+08 | D36: 350 | E36: 1- Kazanılmamış Primler Karşılığı - Net | F36: =INDIRECT("'Pasif Detay'!"&ADDRESS(IFERROR(MATCH(VLOOKUP($E$3,$BC$3:$BE$140,2,0),'Pasif Detay'!$B:$B,0),MATCH(9003,'Pasif Detay'!$B:$B,0)+1),MATCH(D36,'Pasif Detay'!$5:$5,0))) -> 5.0018067e+11 | BC36: SS Atlas Sigorta Kooperatifi | BD36: 1046
A37: 133 | B37: 3- Bağlı Ortaklıklardan Alacaklar | C37: =INDIRECT("'Aktif Detay'!"&ADDRESS(IFERROR(MATCH(VLOOKUP($E$3,$BC$3:$BE$140,2,0),'Aktif Detay'!$B:$B,0),MATCH(9003,'Aktif Detay'!$B:$B,0)+1),MATCH(A37,'Aktif Detay'!$5:$5,0))) -> 57216873 | D37: 351 | E37: 2- Devam Eden Riskler Karşılığı - Net | F37: =INDIRECT("'Pasif Detay'!"&ADDRESS(IFERROR(MATCH(VLOOKUP($E$3,$BC$3:$BE$140,2,0),'Pasif Detay'!$B:$B,0),MATCH(9003,'Pasif Detay'!$B:$B,0)+1),MATCH(D37,'Pasif Detay'!$5:$5,0))) -> 1.817705e+10 | BC37: Türkiye Katılım Sigorta AŞ | BD37: 1048
A38: 134 | B38: 4- Müşterek Yönetime Tabi Teşebbüslerden Alacaklar | C38: =INDIRECT("'Aktif Detay'!"&ADDRESS(IFERROR(MATCH(VLOOKUP($E$3,$BC$3:$BE$140,2,0),'Aktif Detay'!$B:$B,0),MATCH(9003,'Aktif Detay'!$B:$B,0)+1),MATCH(A38,'Aktif Detay'!$5:$5,0))) -> 39118576 | D38: 352 | E38: 3- Hayat Matematik Karşılığı - Net | F38: =INDIRECT("'Pasif Detay'!"&ADDRESS(IFERROR(MATCH(VLOOKUP($E$3,$BC$3:$BE$140,2,0),'Pasif Detay'!$B:$B,0),MATCH(9003,'Pasif Detay'!$B:$B,0)+1),MATCH(D38,'Pasif Detay'!$5:$5,0))) -> 5.7002471e+10 | BC38: Ana Sigorta AŞ | BD38: 1049
A39: 135 | B39: 5- Personelden Alacaklar | C39: =INDIRECT("'Aktif Detay'!"&ADDRESS(IFERROR(MATCH(VLOOKUP($E$3,$BC$3:$BE$140,2,0),'Aktif Detay'!$B:$B,0),MATCH(9003,'Aktif Detay'!$B:$B,0)+1),MATCH(A39,'Aktif Detay'!$5:$5,0))) -> 19016184 | D39: 353 | E39: 4- Muallak Hasar ve Tazminat Karşılığı - Net | F39: =INDIRECT("'Pasif Detay'!"&ADDRESS(IFERROR(MATCH(VLOOKUP($E$3,$BC$3:$BE$140,2,0),'Pasif Detay'!$B:$B,0),MATCH(9003,'Pasif Detay'!$B:$B,0)+1),MATCH(D39,'Pasif Detay'!$5:$5,0))) -> 4.0508025e+11 | BC39: Arex Sigorta AŞ | BD39: 1051
A40: 136 | B40: 6- Diğer İlişkili Taraflardan Alacaklar | C40: =INDIRECT("'Aktif Detay'!"&ADDRESS(IFERROR(MATCH(VLOOKUP($E$3,$BC$3:$BE$140,2,0),'Aktif Detay'!$B:$B,0),MATCH(9003,'Aktif Detay'!$B:$B,0)+1),MATCH(A40,'Aktif Detay'!$5:$5,0))) -> 2.8315285e+08 | D40: 354 | E40: 5- İkramiye ve İndirimler Karşılığı - Net | F40: =INDIRECT("'Pasif Detay'!"&ADDRESS(IFERROR(MATCH(VLOOKUP($E$3,$BC$3:$BE$140,2,0),'Pasif Detay'!$B:$B,0),MATCH(9003,'Pasif Detay'!$B:$B,0)+1),MATCH(D40,'Pasif Detay'!$5:$5,0))) -> 3.3136907e+09 | BC40: Prive Sigorta AŞ | BD40: 1052
A41: 137 | B41: 7- İlişkili Taraflardan Alacaklar Reeskontu (-) | C41: =INDIRECT("'Aktif Detay'!"&ADDRESS(IFERROR(MATCH(VLOOKUP($E$3,$BC$3:$BE$140,2,0),'Aktif Detay'!$B:$B,0),MATCH(9003,'Aktif Detay'!$B:$B,0)+1),MATCH(A41,'Aktif Detay'!$5:$5,0))) -> 0 | D41: 359 | E41: 6- Diğer Teknik Karşılıklar - Net | F41: =INDIRECT("'Pasif Detay'!"&ADDRESS(IFERROR(MATCH(VLOOKUP($E$3,$BC$3:$BE$140,2,0),'Pasif Detay'!$B:$B,0),MATCH(9003,'Pasif Detay'!$B:$B,0)+1),MATCH(D41,'Pasif Detay'!$5:$5,0))) -> 1.1036498e+09 | BC41: Hepiyi Sigorta AŞ | BD41: 1053
A42: 138 | B42: 8- İlişkili Taraflardan Şüpheli Alacaklar | C42: =INDIRECT("'Aktif Detay'!"&ADDRESS(IFERROR(MATCH(VLOOKUP($E$3,$BC$3:$BE$140,2,0),'Aktif Detay'!$B:$B,0),MATCH(9003,'Aktif Detay'!$B:$B,0)+1),MATCH(A42,'Aktif Detay'!$5:$5,0))) -> 1551278.1 | E42: F- Ödenecek Vergi ve Benzeri Diğer Yükümlülükler İle Karşılıkları | F42: =SUM(F43:F49) -> 3.374427e+10 | BC42: Aveon Global Sigorta AŞ | BD42: 1054
...

Sheet Aktif Detay
A1: BİLANÇO
A2: Aktif Detay
A3: 01.01.2026-30.06.2026
D5: 1 | E5: 10 | F5: 100 | G5: 101 | H5: 102 | I5: 103 | J5: 106 | K5: 109 | L5: 11 | M5: 110 | N5: 111 | O5: 112 | P5: 115 | Q5: 116 | R5: 117 | S5: 118 | T5: 119 | U5: 12 | V5: 120 | W5: 121 | X5: 122 | Y5: 123 | Z5: 124 | AA5: 125 | AB5: 126 | AC5: 127 | AD5: 128 | AE5: 129 | AF5: 13 | AG5: 131 | AH5: 132 | AI5: 133 | AJ5: 134 | AK5: 135 | AL5: 136 | AM5: 137 | AN5: 138 | AO5: 139 | AP5: 14 | AQ5: 141 | AR5: 142 | AS5: 145 | AT5: 146 | AU5: 147 | AV5: 148 | AW5: 149 | AX5: 18 | AY5: 180 | AZ5: 181 | BA5: 183 | BB5: 189 | BC5: 19 | BD5: 192 | BE5: 193 | BF5: 194 | BG5: 195 | BH5: 196 | BI5: 197 | BJ5: 198 | BK5: 199 | BL5: 2 | BM5: 22 | BN5: 220 | BO5: 221 | BP5: 222 | BQ5: 223 | BR5: 224 | BS5: 225 | BT5: 226 | BU5: 227 | BV5: 228 | BW5: 229 | BX5: 23 | BY5: 231 | BZ5: 232 | CA5: 233 | CB5: 234 | CC5: 235 | CD5: 236 | CE5: 237 | CF5: 238 | CG5: 239 | CH5: 24 | CI5: 241 | CJ5: 242 | CK5: 245 | CL5: 246 | CM5: 247 | CN5: 248 | CO5: 249 | CP5: 25 | CQ5: 250 | CR5: 251 | CS5: 252 | CT5: 253 | CU5: 254 | CV5: 255 | CW5: 256 | CX5: 257 | CY5: 258 | CZ5: 259 | DA5: 26 | DB5: 260 | DC5: 261 | DD5: 262 | DE5: 263 | DF5: 264 | DG5: 265 | DH5: 266 | DI5: 267 | DJ5: 268 | DK5: 269 | DL5: 27 | DM5: 270 | DN5: 271 | DO5: 272 | DP5: 273 | DQ5: 277 | DR5: 278 | DS5: 279 | DT5: 28 | DU5: 280 | DV5: 283 | DW5: 289 | DX5: 29 | DY5: 290 | DZ5: 291 | EA5: 292 | EB5: 293 | EC5: 294 | ED5: 297 | EE5: 298 | EF5: 299
A6: Şirket Adı | B6: Şirket Kodu | C6: Şirket Tipi | D6: Cari Varlıklar | E6: Nakit ve Nakit Benzeri Varlıklar | F6: Kasa | G6: Alınan Çekler | H6: Bankalar | I6: Verilen Çekler ve Ödeme Emirleri (-); | J6: Banka Garantili ve Üç Aydan Kısa Vadeli Kredi Kartı Alacakları | K6: Diğer Nakit ve Nakit Benzeri Varlıklar | L6: Finansal Varlıklar ile Riski Sigortalılara Ait Finansal Yatırımlar | M6: Satılmaya Hazır Finansal Varlıklar | N6: Vadeye Kadar Elde Tutulacak Finansal Varlıklar | O6: Alım Satım Amaçlı Finansal Varlıklar | P6: Krediler | Q6: Krediler Karşılığı (-); | R6: Riski Hayat Poliçesi Sahiplerine Ait Finansal Yatırımlar | S6: Şirket Hissesi | T6: Finansal Varlıklar Değer Düşüklüğü Karşılığı (-); | U6: Esas Faaliyetlerden Alacaklar | V6: Sigortacılık Faaliyetlerinden Alacaklar | W6: Sigortacılık Faaliyetlerinden Alacaklar Karşılığı (-); | X6: Reasürans Faaliyetlerinden Alacaklar | Y6: Reasürans Faaliyetlerinden Alacaklar Karşılığı (-); | Z6: Sigorta ve Reasürans Şirketleri Nezdindeki Depolar | AA6: Sigortalılara Krediler (İkrazlar); | AB6: Sigortalılara Krediler (İkrazlar); Karşılığı (-); | AC6: Emeklilik Faaliyetlerinden Alacaklar | AD6: Esas Faaliyetlerden Kaynaklanan Şüpheli Alacaklar | AE6: Esas Faaliyetlerden Kaynaklanan Şüpheli Alacaklar Karşılığı (-); | AF6: İlişkili Taraflardan Alacaklar | AG6: Ortaklardan Alacaklar | AH6: İştiraklerden Alacaklar | AI6: Bağlı Ortaklıklardan Alacaklar | AJ6: Müşterek Yönetime Tabi Teşebbüslerden Alacaklar | AK6: Personelden Alacaklar | AL6: Diğer İlişkili Taraflardan Alacaklar | AM6: İlişkili Taraflardan Alacaklar Reeskontu (-); | AN6: İlişkili Taraflardan Şüpheli Alacaklar | AO6: İlişkili Taraflardan Şüpheli Alacaklar Karşılığı (-); | AP6: Diğer Alacaklar | AQ6: Finansal Kiralama Alacakları | AR6: Kazanılmamış Finansal Kiralama Faiz Gelirleri (-); | AS6: Verilen Depozito ve Teminatlar | AT6: Diğer Çeşitli Alacaklar | AU6: Diğer Çeşitli Alacaklar Reeskontu (-); | AV6: Şüpheli Diğer Alacaklar | AW6: Şüpheli Diğer Alacaklar Karşılığı (-); | AX6: Gelecek Aylara Ait Giderler ve Gelir Tahakkukları | AY6: Gelecek Aylara Ait Giderler ve Gelir Tahakkukları | AZ6: Tahakkuk Etmiş Faiz ve Kira Gelirleri | BA6: Gelir Tahakkukları | BB6: Gelecek Aylara Ait Diğer Giderler ve Gelir Tahakkukları | BC6: Diğer Cari Varlıklar | BD6: Gelecek Aylar İhtiyacı Stoklar | BE6: Peşin Ödenen Vergiler ve Fonlar | BF6: Ertelenmiş Vergi Varlıkları | BG6: İş Avansları | BH6: Personele Verilen Avanslar | BI6: Sayım ve Tesellüm Noksanları | BJ6: Diğer Çeşitli Cari Varlıklar (+/-); | BK6: Diğer Cari Varlıklar Karşılığı (-); | BL6: Cari Olmayan Varlıklar | BM6: Esas Faaliyetlerden Alacaklar | BN6: Sigortacılık Faaliyetlerinden Alacaklar | BO6: Sigortacılık Faaliyetlerinden Alacaklar Karşılığı (-); | BP6: Reasürans Faaliyetlerinden Alacaklar | BQ6: Reasürans Faaliyetlerinden Alacaklar Karşılığı (-); | BR6: Sigorta ve Reasürans Şirketleri Nezdindeki Depolar | BS6: Sigortalılara Krediler (İkrazlar); | BT6: Sigortalılara Krediler (İkrazlar); Karşılığı (-); | BU6: Emeklilik Faaliyetlerinden Alacaklar | BV6: Esas Faaliyetlerden Kaynaklanan Şüpheli Alacaklar | BW6: Esas Faaliyetlerden Kaynaklanan Şüpheli Alacaklar Karşılığı (-); | BX6: İlişkili Taraflardan Alacaklar | BY6: Ortaklardan Alacaklar | BZ6: İştiraklerden Alacaklar | CA6: Bağlı Ortaklıklardan Alacaklar | CB6: Müşterek Yönetime Tabi Teşebbüslerden Alacaklar | CC6: Personelden Alacaklar | CD6: Diğer İlişkili Taraflardan Alacaklar | CE6: İlişkili Taraflardan Alacaklar Reeskontu (-); | CF6: İlişkili Taraflardan Şüpheli Alacaklar | CG6: İlişkili Taraflardan Şüpheli Alacaklar Karşılığı (-); | CH6: Diğer Alacaklar | CI6: Finansal Kiralama Alacakları | CJ6: Kazanılmamış Finansal Kiralama Faiz Gelirleri | CK6: Verilen Depozito ve Teminatlar | CL6: Diğer Çeşitli Alacaklar | CM6: Diğer Çeşitli Alacaklar Reeskontu (-); | CN6: Şüpheli Diğer Alacaklar | CO6: Şüpheli Diğer Alacaklar Karşılığı (-); | CP6: Finansal Varlıklar | CQ6: Bağlı Menkul Kıymetler | CR6: İştirakler | CS6: İştirakler Sermaye Taahhütleri (-); | CT6: Bağlı Ortaklıklar | CU6: Bağlı Ortaklıklar Sermaye Taahhütleri (-); | CV6: Müşterek Yönetime Tabi Teşebbüsler | CW6: Müşterek Yönetime Tabi Teşebbüsler Sermaye Taahhütleri (-); | CX6: Finansal Varlıklar ve Riski Sigortalılara Ait Finansal Yatırımlar | CY6: Diğer Finansal Varlıklar | CZ6: Finansal Varlıklar Değer Düşüklüğü Karşılığı (-); | DA6: Maddi Varlıklar | DB6: Yatırım Amaçlı Gayrimenkuller | DC6: Yatırım Amaçlı Gayrımenkuller Değer Düşüklüğü Karşılığı(-); | DD6: Kullanım Amaçlı Gayrımenkuller | DE6: Makine ve Teçhizatlar | DF6: Demirbaş ve Tesisatlar | DG6: Motorlu Taşıtlar | DH6: Diğer Maddi Varlıklar (Özel Maliyet Bedelleri Dahil); | DI6: Kiralama Yoluyla Edinilmiş Maddi Varlıklar | DJ6: Birikmiş Amortismanlar (-); | DK6: Maddi Varlıklara İlişkin Verilen Avanslar (Yapılmakta Olan Yatırımlar Dahil); | DL6: Maddi Olmayan Varlıklar | DM6: Haklar | DN6: Şerefiye | DO6: Faaliyet Öncesi Döneme Ait Giderler | DP6: Araştırma ve Geliştirme Giderleri | DQ6: Diğer Maddi Olmayan Varlıklar | DR6: Birikmiş İtfalar (Amortismanlar); (-); | DS6: Maddi Olmayan Varlıklara İlişkin Avanslar | DT6: Gelecek Yıllara Ait Giderler ve Gelir Tahakkukları | DU6: Gelecek Yıllara Ait Giderler ve Gelir Tahakkukları | DV6: Gelir Tahakkukları | DW6: Gelecek Yıllara Ait Diğer Giderler ve Gelir Tahakkukları | DX6: Diğer Cari Olmayan Varlıklar | DY6: Efektif Yabancı Para Hesapları | DZ6: Döviz Hesapları | EA6: Gelecek Yıllar İhtiyacı Stoklar | EB6: Peşin Ödenen Vergiler ve Fonlar | EC6: Ertelenmiş Vergi Varlıkları | ED6: Diğer Çeşitli Cari Olmayan Varlıklar | EE6: Diğer Cari Olmayan Varlıklar Amortismanı (-); | EF6: Diğer Cari Olmayan Varlıklar Karşılığı (-);
A7: Chubb European Group SE Merkezi Fransa Türkiye İstanbul Şubesi | B7: 1001 | C7: HD | D7: 4.3957879e+09 | E7: 2.3519865e+09 | F7: 0 | G7: 0 | H7: 2.3519865e+09 | I7: 0 | J7: 0 | K7: 0 | L7: 0 | M7: 0 | N7: 0 | O7: 0 | P7: 0 | Q7: 0 | R7: 0 | S7: 0 | T7: 0 | U7: 1.7422527e+09 | V7: 1.7800069e+09 | W7: -37754191 | X7: 0 | Y7: 0 | Z7: 0 | AA7: 0 | AB7: 0 | AC7: 0 | AD7: 98949835 | AE7: -98949835 | AF7: 0 | AG7: 0 | AH7: 0 | AI7: 0 | AJ7: 0 | AK7: 0 | AL7: 0 | AM7: 0 | AN7: 0 | AO7: 0 | AP7: 10753225 | AQ7: 0 | AR7: 0 | AS7: 3300000 | AT7: 0 | AU7: 7453225 | AV7: 0 | AW7: 0 | AX7: 2.0141114e+08 | AY7: 1.8079024e+08 | AZ7: 4244659.1 | BA7: 0 | BB7: 16376237 | BC7: 89384376 | BD7: 0 | BE7: 89379127 | BF7: 0 | BG7: 5249.47 | BH7: 0 | BI7: 0 | BJ7: 0 | BK7: 0 | BL7: 1.3623502e+08 | BM7: 0 | BN7: 0 | BO7: 0 | BP7: 0 | BQ7: 0 | BR7: 0 | BS7: 0 | BT7: 0 | BU7: 0 | BV7: 0 | BW7: 0 | BX7: 0 | BY7: 0 | BZ7: 0 | CA7: 0 | CB7: 0 | CC7: 0 | CD7: 0 | CE7: 0 | CF7: 0 | CG7: 0 | CH7: 0 | CI7: 0 | CJ7: 0 | CK7: 0 | CL7: 0 | CM7: 0 | CN7: 0 | CO7: 0 | CP7: 0 | CQ7: 0 | CR7: 0 | CS7: 0 | CT7: 0 | CU7: 0 | CV7: 0 | CW7: 0 | CX7: 0 | CY7: 0 | CZ7: 0 | DA7: 79172978 | DB7: 0 | DC7: 0 | DD7: 0 | DE7: 0 | DF7: 26896417 | DG7: 6122433.6 | DH7: 47512843 | DI7: 45389465 | DJ7: -46748182 | DK7: 0 | DL7: 9733.4 | DM7: 40099.3 | DN7: 0 | DO7: 0 | DP7: 0 | DQ7: 0 | DR7: -30365.9 | DS7: 0 | DT7: 0 | DU7: 0 | DV7: 0 | DW7: 0 | DX7: 57052309 | DY7: 0 | DZ7: 0 | EA7: 0 | EB7: 0 | EC7: 57052309 | ED7: 0 | EE7: 0 | EF7: 0
A8: Aksigorta AŞ | B8: 1003 | C8: HD | D8: 3.7466004e+10 | E8: 1.194898e+10 | F8: 0 | G8: 0 | H8: 7.7062153e+09 | I8: 0 | J8: 4.2427649e+09 | K8: 0 | L8: 1.3858727e+10 | M8: 2.7413061e+09 | N8: 7.4962434e+08 | O8: 1.0364376e+10 | P8: 0 | Q8: 0 | R8: 3420935 | S8: 0 | T8: 0 | U8: 6.1730148e+09 | V8: 6.1453426e+09 | W8: -44925285 | X8: 0 | Y8: -12437103 | Z8: 0 | AA8: 0 | AB8: 0 | AC8: 0 | AD8: 1.1015979e+09 | AE8: -1.0165633e+09 | AF8: 0 | AG8: 0 | AH8: 0 | AI8: 0 | AJ8: 0 | AK8: 0 | AL8: 0 | AM8: 0 | AN8: 0 | AO8: 0 | AP8: 58302555 | AQ8: 0 | AR8: 0 | AS8: 3855137.4 | AT8: 54447417 | AU8: 0 | AV8: 0 | AW8: 0 | AX8: 5.1047353e+09 | AY8: 4.4874231e+09 | AZ8: 0 | BA8: 3249113.7 | BB8: 6.1406311e+08 | BC8: 3.2224377e+08 | BD8: 0 | BE8: 3.2063335e+08 | BF8: 0 | BG8: 13986 | BH8: 1596429 | BI8: 0 | BJ8: 0 | BK8: 0 | BL8: 2.6478346e+09 | BM8: 0 | BN8: 0 | BO8: 0 | BP8: 0 | BQ8: 0 | BR8: 0 | BS8: 0 | BT8: 0 | BU8: 0 | BV8: 0 | BW8: 0 | BX8: 0 | BY8: 0 | BZ8: 0 | CA8: 0 | CB8: 0 | CC8: 0 | CD8: 0 | CE8: 0 | CF8: 0 | CG8: 0 | CH8: 0 | CI8: 0 | CJ8: 0 | CK8: 0 | CL8: 0 | CM8: 0 | CN8: 0 | CO8: 0 | CP8: 17094836 | CQ8: 0 | CR8: 17094836 | CS8: 0 | CT8: 0 | CU8: 0 | CV8: 0 | CW8: 0 | CX8: 0 | CY8: 0 | CZ8: 0 | DA8: 6.0430624e+08 | DB8: 0 | DC8: 0 | DD8: 5328.86 | DE8: 0 | DF8: 2.0295315e+08 | DG8: 794892.03 | DH8: 3.4387403e+08 | DI8: 2.6517207e+08 | DJ8: -2.0849322e+08 | DK8: 0 | DL8: 1.171667e+09 | DM8: 1.3815447e+09 | DN8: 0 | DO8: 0 | DP8: 4.258914e+08 | DQ8: 0 | DR8: -6.3576908e+08 | DS8: 0 | DT8: 17851674 | DU8: 0 | DV8: 0 | DW8: 17851674 | DX8: 8.3691486e+08 | DY8: 0 | DZ8: 0 | EA8: 0 | EB8: 0 | EC8: 8.3691486e+08 | ED8: 0 | EE8: 0 | EF8: 0
A9: Allianz Sigorta AŞ | B9: 1004 | C9: HD | D9: 1.7252027e+11 | E9: 8.246623e+10 | F9: 0 | G9: 0 | H9: 6.8367134e+10 | I9: 0 | J9: 1.4093592e+10 | K9: 5503899.6 | L9: 4.0861727e+10 | M9: 3.9428773e+10 | N9: 0 | O9: 1.4329541e+09 | P9: 0 | Q9: 0 | R9: 0 | S9: 0 | T9: 0 | U9: 3.5078144e+10 | V9: 3.4604999e+10 | W9: -1.4984675e+08 | X9: 7.0298907e+08 | Y9: -80281068 | Z9: 136280.85 | AA9: 0 | AB9: 0 | AC9: 0 | AD9: 2.2304019e+09 | AE9: -2.2302551e+09 | AF9: 74167207 | AG9: 0 | AH9: 0 | AI9: 0 | AJ9: 0 | AK9: 0 | AL9: 74167207 | AM9: 0 | AN9: 0 | AO9: 0 | AP9: 1.7698081e+08 | AQ9: 0 | AR9: 0 | AS9: 0 | AT9: 1.7698081e+08 | AU9: 0 | AV9: 6490936.4 | AW9: -6490936.4 | AX9: 1.218222e+10 | AY9: 1.1586449e+10 | AZ9: 16619.25 | BA9: 0 | BB9: 5.9575468e+08 | BC9: 1.6807961e+09 | BD9: 0 | BE9: 1.6699737e+09 | BF9: 0 | BG9: 2992232 | BH9: 7830193.3 | BI9: 0 | BJ9: 0 | BK9: 0 | BL9: 2.3990428e+10 | BM9: 0 | BN9: 0 | BO9: 0 | BP9: 0 | BQ9: 0 | BR9: 0 | BS9: 0 | BT9: 0 | BU9: 0 | BV9: 0 | BW9: 0 | BX9: 0 | BY9: 0 | BZ9: 0 | CA9: 0 | CB9: 0 | CC9: 0 | CD9: 0 | CE9: 0 | CF9: 0 | CG9: 0 | CH9: 385529.71 | CI9: 0 | CJ9: 0 | CK9: 385529.71 | CL9: 0 | CM9: 0 | CN9: 0 | CO9: 0 | CP9: 1.8436745e+10 | CQ9: 0 | CR9: 79149602 | CS9: 0 | CT9: 1.8357596e+10 | CU9: 0 | CV9: 0 | CW9: 0 | CX9: 0 | CY9: 0 | CZ9: 0 | DA9: 2.1631854e+09 | DB9: 5.2510805e+08 | DC9: 0 | DD9: 9.807547e+08 | DE9: 0 | DF9: 9.2680232e+08 | DG9: 780985.4 | DH9: 52367265 | DI9: 2.9255706e+08 | DJ9: -6.4971626e+08 | DK9: 34531303 | DL9: 1.3602913e+09 | DM9: 1.4831009e+09 | DN9: 0 | DO9: 0 | DP9: 0 | DQ9: 0 | DR9: -6.8152029e+08 | DS9: 5.5871063e+08 | DT9: 63102545 | DU9: 0 | DV9: 0 | DW9: 63102545 | DX9: 1.9667177e+09 | DY9: 0 | DZ9: 0 | EA9: 0 | EB9: 0 | EC9: 1.9667177e+09 | ED9: 0 | EE9: 0 | EF9: 0
A10: Anadolu Anonim Türk Sigorta Şirketi | B10: 1005 | C10: HD | D10: 1.3950934e+11 | E10: 3.8872587e+10 | F10: 251923.29 | G10: 0 | H10: 2.8029228e+10 | I10: -6311.09 | J10: 1.0843114e+10 | K10: 0 | L10: 6.0995842e+10 | M10: 3.0640487e+10 | N10: 0 | O10: 3.0355355e+10 | P10: 0 | Q10: 0 | R10: 0 | S10: 0 | T10: 0 | U10: 2.7211597e+10 | V10: 2.0745786e+10 | W10: -3.8231963e+08 | X10: 3.6255076e+09 | Y10: 0 | Z10: 3.2226233e+09 | AA10: 0 | AB10: 0 | AC10: 0 | AD10: 3.5813247e+09 | AE10: -3.5813247e+09 | AF10: 0 | AG10: 0 | AH10: 0 | AI10: 0 | AJ10: 0 | AK10: 0 | AL10: 0 | AM10: 0 | AN10: 0 | AO10: 0 | AP10: 8.779279e+08 | AQ10: 0 | AR10: 0 | AS10: 0 | AT10: 8.779279e+08 | AU10: 0 | AV10: 0 | AW10: 0 | AX10: 1.0480458e+10 | AY10: 1.0473124e+10 | AZ10: 0 | BA10: 5915310.5 | BB10: 1418943.6 | BC10: 1.0709242e+09 | BD10: 7188318.1 | BE10: 0 | BF10: 0 | BG10: 1.0611067e+09 | BH10: 2629221.1 | BI10: 0 | BJ10: 1e-05 | BK10: 0 | BL10: 1.1824725e+10 | BM10: 0 | BN10: 0 | BO10: 0 | BP10: 0 | BQ10: 0 | BR10: 0 | BS10: 0 | BT10: 0 | BU10: 0 | BV10: 0 | BW10: 0 | BX10: 0 | BY10: 0 | BZ10: 0 | CA10: 0 | CB10: 0 | CC10: 0 | CD10: 0 | CE10: 0 | CF10: 0 | CG10: 0 | CH10: 552554.61 | CI10: 0 | CJ10: 0 | CK10: 324554.61 | CL10: 228000 | CM10: 0 | CN10: 0 | CO10: 0 | CP10: 8849400000 | CQ10: 0 | CR10: 8849400000 | CS10: 0 | CT10: 0 | CU10: 0 | CV10: 0 | CW10: 0 | CX10: 0 | CY10: 0 | CZ10: 0 | DA10: 1.5148686e+09 | DB10: 856337000 | DC10: 0 | DD10: 166171600 | DE10: 4.0661125e+08 | DF10: 43735232 | DG10: 96463430 | DH10: 67804868 | DI10: 3.7997787e+08 | DJ10: -5.022326e+08 | DK10: 0 | DL10: 1.0918173e+09 | DM10: 142 | DN10: 16250000 | DO10: 0 | DP10: 86866491 | DQ10: 9.1955016e+08 | DR10: -6.5589886e+08 | DS10: 7.2504932e+08 | DT10: 1.047453e+08 | DU10: 1.047453e+08 | DV10: 0 | DW10: 0 | DX10: 263340929 | DY10: 0 | DZ10: 0 | EA10: 0 | EB10: 0 | EC10: 263340929 | ED10: 0 | EE10: 0 | EF10: 0
A11: Ankara Anonim Türk Sigorta Şirketi | B11: 1006 | C11: HD | D11: 2.786742e+10 | E11: 1.7205316e+10 | F11: 0 | G11: 0 | H11: 1.3214205e+10 | I11: 0 | J11: 3.9911115e+09 | K11: 0 | L11: 6.1452956e+09 | M11: 0 | N11: 1.2800286e+09 | O11: 4.865267e+09 | P11: 0 | Q11: 0 | R11: 0 | S11: 0 | T11: 0 | U11: 2.5346077e+09 | V11: 2.541821e+09 | W11: -8303424.2 | X11: 0 | Y11: 0 | Z11: 0 | AA11: 0 | AB11: 0 | AC11: 0 | AD11: 7.5611973e+08 | AE11: -7.5502956e+08 | AF11: 2186171.2 | AG11: 314660 | AH11: 0 | AI11: 0 | AJ11: 0 | AK11: -0.52 | AL11: 1871511.7 | AM11: 0 | AN11: 0 | AO11: 0 | AP11: 1672585 | AQ11: 0 | AR11: 0 | AS11: 810199.07 | AT11: 862385.95 | AU11: 0 | AV11: 0 | AW11: 0 | AX11: 1.4523094e+09 | AY11: 1.3387457e+09 | AZ11: 0 | BA11: 0 | BB11: 1.1356369e+08 | BC11: 5.2603231e+08 | BD11: 0 | BE11: 5.1820727e+08 | BF11: 0 | BG11: 708277.27 | BH11: 0 | BI11: 0 | BJ11: 7116766.8 | BK11: 0 | BL11: 1.9246251e+09 | BM11: 0 | BN11: 0 | BO11: 0 | BP11: 0 | BQ11: 0 | BR11: 0 | BS11: 0 | BT11: 0 | BU11: 0 | BV11: 0 | BW11: 0 | BX11: 0 | BY11: 0 | BZ11: 0 | CA11: 0 | CB11: 0 | CC11: 0 | CD11: 0 | CE11: 0 | CF11: 0 | CG11: 0 | CH11: 189769.37 | CI11: 0 | CJ11: 0 | CK11: 189769.37 | CL11: 0 | CM11: 0 | CN11: 0 | CO11: 0 | CP11: 29757356 | CQ11: 10238660 | CR11: 20000000 | CS11: 0 | CT11: 0 | CU11: 0 | CV11: 0 | CW11: 0 | CX11: 0 | CY11: 0 | CZ11: -481304.27 | DA11: 1.3543795e+09 | DB11: 21605000 | DC11: 0 | DD11: 1.3229323e+09 | DE11: 0 | DF11: 30890811 | DG11: 56692896 | DH11: 2390821 | DI11: 1634922.7 | DJ11: -84417185 | DK11: 2650000 | DL11: 14514675 | DM11: 38108320 | DN11: 0 | DO11: 0 | DP11: 0 | DQ11: 0 | DR11: -23593645 | DS11: 0 | DT11: 0 | DU11: 0 | DV11: 0 | DW11: 0 | DX11: 5.2578379e+08 | DY11: 0 | DZ11: 0 | EA11: 0 | EB11: 0 | EC11: 5.2578379e+08 | ED11: 0 | EE11: 0 | EF11: 0
A12: Atradius Crédito y Caución S.A. de Seguros y Reaseguros, İstanbul Şubesi | B12: 1007 | C12: HD | D12: 1.4992056e+09 | E12: 7.9451428e+08 | F12: 0 | G12: 0 | H12: 7.9451428e+08 | I12: 0 | J12: 0 | K12: 0 | L12: 0 | M12: 0 | N12: 0 | O12: 0 | P12: 0 | Q12: 0 | R12: 0 | S12: 0 | T12: 0 | U12: 5.910541e+08 | V12: 5.910541e+08 | W12: 0 | X12: 0 | Y12: 0 | Z12: 0 | AA12: 0 | AB12: 0 | AC12: 0 | AD12: 943412 | AE12: -943412 | AF12: 16309056 | AG12: 0 | AH12: 0 | AI12: 0 | AJ12: 0 | AK12: 333297.62 | AL12: 15975759 | AM12: 0 | AN12: 0 | AO12: 0 | AP12: 28963.25 | AQ12: 0 | AR12: 0 | AS12: 0 | AT12: 28963.25 | AU12: 0 | AV12: 0 | AW12: 0 | AX12: 77429480 | AY12: 65595624 | AZ12: 0 | BA12: 0 | BB12: 11833856 | BC12: 19869727 | BD12: 0 | BE12: 19869727 | BF12: 0 | BG12: 0 | BH12: 0 | BI12: 0 | BJ12: 0 | BK12: 0 | BL12: 1.9353974e+08 | BM12: 61831792 | BN12: 61831792 | BO12: 0 | BP12: 0 | BQ12: 0 | BR12: 0 | BS12: 0 | BT12: 0 | BU12: 0 | BV12: 0 | BW12: 0 | BX12: 8044089.9 | BY12: 8044089.9 | BZ12: 0 | CA12: 0 | CB12: 0 | CC12: 0 | CD12: 0 | CE12: 0 | CF12: 0 | CG12: 0 | CH12: 0 | CI12: 0 | CJ12: 0 | CK12: 0 | CL12: 0 | CM12: 0 | CN12: 0 | CO12: 0 | CP12: 0 | CQ12: 0 | CR12: 0 | CS12: 0 | CT12: 0 | CU12: 0 | CV12: 0 | CW12: 0 | CX12: 0 | CY12: 0 | CZ12: 0 | DA12: 22478008 | DB12: 0 | DC12: 0 | DD12: 0 | DE12: 0 | DF12: 9269895.5 | DG12: 0 | DH12: 0 | DI12: 42631436 | DJ12: -29423323 | DK12: 0 | DL12: 0 | DM12: 0 | DN12: 0 | DO12: 0 | DP12: 0 | DQ12: 235635.56 | DR12: -235635.56 | DS12: 0 | DT12: 12863584 | DU12: 12863584 | DV12: 0 | DW12: 0 | DX12: 88322267 | DY12: 0 | DZ12: 0 | EA12: 0 | EB12: 0 | EC12: 88322267 | ED12: 0 | EE12: 0 | EF12: 0
A13: Unico Sigorta AŞ | B13: 1008 | C13: HD | D13: 2.8194336e+10 | E13: 1.3201421e+10 | F13: 0 | G13: 0 | H13: 1.3056162e+10 | I13: 0 | J13: 1.4525944e+08 | K13: 0 | L13: 8.6439142e+09 | M13: 3.3112256e+09 | N13: 1.3632073e+09 | O13: 3.9694813e+09 | P13: 0 | Q13: 0 | R13: 0 | S13: 0 | T13: 0 | U13: 2.9193832e+09 | V13: 3.0722643e+09 | W13: -1.5288109e+08 | X13: 0 | Y13: 0 | Z13: 0 | AA13: 0 | AB13: 0 | AC13: 0 | AD13: 7.8863535e+08 | AE13: -7.8863535e+08 | AF13: 0 | AG13: 0 | AH13: 0 | AI13: 0 | AJ13: 0 | AK13: 0 | AL13: 0 | AM13: 0 | AN13: 0 | AO13: 0 | AP13: 60303342 | AQ13: 0 | AR13: 0 | AS13: 5960857.4 | AT13: 57895501 | AU13: -3553016.5 | AV13: 0 | AW13: 0 | AX13: 2.5457683e+09 | AY13: 1.7691258e+09 | AZ13: 0 | BA13: 0 | BB13: 7.7664258e+08 | BC13: 8.2354528e+08 | BD13: 0 | BE13: 7.6180854e+08 | BF13: 0 | BG13: 60813031 | BH13: 923710.72 | BI13: 0 | BJ13: 0 | BK13: 0 | BL13: 4.6477041e+09 | BM13: 0 | BN13: 0 | BO13: 0 | BP13: 0 | BQ13: 0 | BR13: 0 | BS13: 0 | BT13: 0 | BU13: 0 | BV13: 0 | BW13: 0 | BX13: 0 | BY13: 0 | BZ13: 0 | CA13: 0 | CB13: 0 | CC13: 0 | CD13: 0 | CE13: 0 | CF13: 0 | CG13: 0 | CH13: 50000 | CI13: 0 | CJ13: 0 | CK13: 50000 | CL13: 0 | CM13: 0 | CN13: 0 | CO13: 0 | CP13: 16651655 | CQ13: 16651655 | CR13: 0 | CS13: 0 | CT13: 0 | CU13: 0 | CV13: 0 | CW13: 0 | CX13: 0 | CY13: 0 | CZ13: 0 | DA13: 4.1254977e+09 | DB13: 3925570000 | DC13: 0 | DD13: 0 | DE13: 0 | DF13: 81241328 | DG13: 11693046 | DH13: 15162031 | DI13: 2.2078778e+08 | DJ13: -1.2895644e+08 | DK13: 0 | DL13: 2.9295378e+08 | DM13: 89246554 | DN13: 0 | DO13: 0 | DP13: 2.6988059e+08 | DQ13: 0 | DR13: -66173367 | DS13: 0 | DT13: 0 | DU13: 0 | DV13: 0 | DW13: 0 | DX13: 2.1255097e+08 | DY13: 0 | DZ13: 0 | EA13: 0 | EB13: 0 | EC13: 2.1255097e+08 | ED13: 0 | EE13: 0 | EF13: 0
A14: Axa Sigorta AŞ | B14: 1009 | C14: HD | D14: 1.3150271e+11 | E14: 3.1841853e+10 | F14: 0 | G14: 0 | H14: 1.8738426e+10 | I14: 0.1 | J14: 1.3103428e+10 | K14: 0 | L14: 54882147208 | M14: 4.0377565e+10 | N14: 1.4506582e+10 | O14: 0 | P14: 0 | Q14: 0 | R14: 0 | S14: 0 | T14: -2000000 | U14: 2.9988149e+10 | V14: 2.778292e+10 | W14: -5.0686494e+08 | X14: 0 | Y14: 0 | Z14: 2.7120944e+09 | AA14: 0 | AB14: 0 | AC14: 0 | AD14: 3.3560762e+09 | AE14: -3.3560762e+09 | AF14: 348425.38 | AG14: 0 | AH14: 0 | AI14: 0 | AJ14: 0 | AK14: 0 | AL14: 348425.38 | AM14: 0 | AN14: 0 | AO14: 0 | AP14: 1.3003083e+09 | AQ14: 0 | AR14: 0 | AS14: 2463688.8 | AT14: 1.2978446e+09 | AU14: 0 | AV14: 128924.89 | AW14: -128924.89 | AX14: 1.3052836e+10 | AY14: 9.0370235e+09 | AZ14: 0 | BA14: 40064744 | BB14: 3.9757474e+09 | BC14: 4.3706622e+08 | BD14: 95441303 | BE14: 3.4120601e+08 | BF14: 0 | BG14: 0 | BH14: 418909.49 | BI14: 0 | BJ14: 0 | BK14: 0 | BL14: 2.7048193e+09 | BM14: 0 | BN14: 0 | BO14: 0 | BP14: 0 | BQ14: 0 | BR14: 0 | BS14: 0 | BT14: 0 | BU14: 0 | BV14: 0 | BW14: 0 | BX14: 0 | BY14: 0 | BZ14: 0 | CA14: 0 | CB14: 0 | CC14: 0 | CD14: 0 | CE14: 0 | CF14: 0 | CG14: 0 | CH14: 0 | CI14: 0 | CJ14: 0 | CK14: 0 | CL14: 0 | CM14: 0 | CN14: 0 | CO14: 0 | CP14: 17262968 | CQ14: 17262968 | CR14: 0 | CS14: 0 | CT14: 0 | CU14: 0 | CV14: 0 | CW14: 0 | CX14: 0 | CY14: 0 | CZ14: 0 | DA14: 1.1779791e+09 | DB14: 5.100684e+08 | DC14: 0 | DD14: 54993766 | DE14: 0 | DF14: 4.5664951e+08 | DG14: 70886863 | DH14: 26470005 | DI14: 2.5826027e+08 | DJ14: -4.6571734e+08 | DK14: 2.6636762e+08 | DL14: 1.061127e+09 | DM14: 1.8323254e+09 | DN14: 2.2724129e+08 | DO14: 0 | DP14: 0 | DQ14: 2801468 | DR14: -1.0012411e+09 | DS14: 0 | DT14: 0 | DU14: 0 | DV14: 0 | DW14: 0 | DX14: 4.4845023e+08 | DY14: 0 | DZ14: 0 | EA14: 0 | EB14: 0 | EC14: 4.4845023e+08 | ED14: 0 | EE14: 0 | EF14: 0
A15: BNP Paribas Cardif Sigorta AŞ | B15: 1010 | C15: HD | D15: 7.8883816e+09 | E15: 3.3896503e+09 | F15: 0 | G15: 0 | H15: 3.3605842e+09 | I15: 0 | J15: 29066035 | K15: 0 | L15: 3.2850177e+09 | M15: 4.4041404e+08 | N15: 0 | O15: 2.8446036e+09 | P15: 0 | Q15: 0 | R15: 0 | S15: 0 | T15: 0 | U15: 4.6276257e+08 | V15: 4.6254299e+08 | W15: 0 | X15: 219574.25 | Y15: 0 | Z15: 0 | AA15: 0 | AB15: 0 | AC15: 0 | AD15: 0 | AE15: 0 | AF15: 0 | AG15: 0 | AH15: 0 | AI15: 0 | AJ15: 0 | AK15: 0 | AL15: 0 | AM15: 0 | AN15: 0 | AO15: 0 | AP15: 0 | AQ15: 0 | AR15: 0 | AS15: 0 | AT15: 0 | AU15: 0 | AV15: 0 | AW15: 0 | AX15: 7.5097189e+08 | AY15: 7.2503172e+08 | AZ15: 0 | BA15: 0 | BB15: 25940177 | BC15: -20763.79 | BD15: 0 | BE15: 0 | BF15: 0 | BG15: 0 | BH15: 0 | BI15: 0 | BJ15: -20763.79 | BK15: 0 | BL15: 5.5106083e+09 | BM15: 0 | BN15: 0 | BO15: 0 | BP15: 0 | BQ15: 0 | BR15: 0 | BS15: 0 | BT15: 0 | BU15: 0 | BV15: 0 | BW15: 0 | BX15: 0 | BY15: 0 | BZ15: 0 | CA15: 0 | CB15: 0 | CC15: 0 | CD15: 0 | CE15: 0 | CF15: 0 | CG15: 0 | CH15: 0 | CI15: 0 | CJ15: 0 | CK15: 0 | CL15: 0 | CM15: 0 | CN15: 0 | CO15: 0 | CP15: 0 | CQ15: 0 | CR15: 0 | CS15: 0 | CT15: 0 | CU15: 0 | CV15: 0 | CW15: 0 | CX15: 0 | CY15: 0 | CZ15: 0 | DA15: 23339282 | DB15: 0 | DC15: 0 | DD15: 0 | DE15: 0 | DF15: 36614124 | DG15: 0 | DH15: 617504.61 | DI15: 18974456 | DJ15: -32866802 | DK15: 0 | DL15: 94570717 | DM15: 1.5874951e+08 | DN15: 0 | DO15: 0 | DP15: 0 | DQ15: 0 | DR15: -64178793 | DS15: 0 | DT15: 5.3589169e+09 | DU15: 5.3589169e+09 | DV15: 0 | DW15: 0.01 | DX15: 33781425 | DY15: 0 | DZ15: 0 | EA15: 0 | EB15: 0 | EC15: 33781425 | ED15: 0 | EE15: 0 | EF15: 0
A16: Coface Sigorta AŞ | B16: 1011 | C16: HD | D16: 1.7614077e+09 | E16: 6.6890541e+08 | F16: 22.12 | G16: 0 | H16: 6.6890539e+08 | I16: 0 | J16: 0 | K16: 0 | L16: 0 | M16: 0 | N16: 0 | O16: 0 | P16: 0 | Q16: 0 | R16: 0 | S16: 0 | T16: 0 | U16: 8.7057473e+08 | V16: 9.1660184e+08 | W16: -47257341 | X16: 1230233.7 | Y16: 0 | Z16: 0 | AA16: 0 | AB16: 0 | AC16: 0 | AD16: 16439277 | AE16: -16439277 | AF16: 7612486.9 | AG16: 0 | AH16: 0 | AI16: 0 | AJ16: 0 | AK16: 63.64 | AL16: 7612423.3 | AM16: 0 | AN16: 0 | AO16: 0 | AP16: 4001411.1 | AQ16: 0 | AR16: 0 | AS16: 187736 | AT16: 3813675.1 | AU16: 0 | AV16: 0 | AW16: 0 | AX16: 1.9420005e+08 | AY16: 1.6394278e+08 | AZ16: 0 | BA16: 25106205 | BB16: 5151069 | BC16: 16113578 | BD16: 0 | BE16: 16113578 | BF16: 0 | BG16: -0.37 | BH16: 0 | BI16: 0 | BJ16: 0 | BK16: 0 | BL16: 3.5594331e+08 | BM16: 175585203 | BN16: 175585203 | BO16: 0 | BP16: 0 | BQ16: 0 | BR16: 0 | BS16: 0 | BT16: 0 | BU16: 0 | BV16: 0 | BW16: 0 | BX16: 0 | BY16: 0 | BZ16: 0 | CA16: 0 | CB16: 0 | CC16: 0 | CD16: 0 | CE16: 0 | CF16: 0 | CG16: 0 | CH16: 0 | CI16: 0 | CJ16: 0 | CK16: 0 | CL16: 0 | CM16: 0 | CN16: 0 | CO16: 0 | CP16: 0 | CQ16: 0 | CR16: 0 | CS16: 0 | CT16: 0 | CU16: 0 | CV16: 0 | CW16: 0 | CX16: 0 | CY16: 0 | CZ16: 0 | DA16: 28790565 | DB16: 0 | DC16: 0 | DD16: 0 | DE16: 0 | DF16: 11076951 | DG16: 0 | DH16: 0 | DI16: 56031561 | DJ16: -38317947 | DK16: 0 | DL16: 6255841.2 | DM16: 0 | DN16: 0 | DO16: 0 | DP16: 0 | DQ16: 15737724 | DR16: -9481883 | DS16: 0 | DT16: 36944153 | DU16: 36944153 | DV16: 0 | DW16: 0 | DX16: 108367548 | DY16: 0 | DZ16: 0 | EA16: 0 | EB16: 0 | EC16: 108367548 | ED16: 0 | EE16: 0 | EF16: 0
A17: Corpus Sigorta AŞ | B17: 1012 | C17: HD | D17: 1.759045e+10 | E17: 9.7434663e+09 | F17: 0 | G17: 0 | H17: 9.2544601e+09 | I17: 0 | J17: 4.8900617e+08 | K17: 0 | L17: 5.0267871e+09 | M17: 0 | N17: 0 | O17: 5.0267871e+09 | P17: 0 | Q17: 0 | R17: 0 | S17: 0 | T17: 0 | U17: 1.772391e+09 | V17: 1.9703778e+09 | W17: -1.9798674e+08 | X17: 0 | Y17: 0 | Z17: 0 | AA17: 0 | AB17: 0 | AC17: 0 | AD17: 1.0715331e+08 | AE17: -1.0715331e+08 | AF17: 0 | AG17: 0 | AH17: 0 | AI17: 0 | AJ17: 0 | AK17: 0 | AL17: 0 | AM17: 0 | AN17: 0 | AO17: 0 | AP17: 35897023 | AQ17: 0 | AR17: 0 | AS17: 31318303 | AT17: 4578719.9 | AU17: 0 | AV17: 0 | AW17: 0 | AX17: 1.0118809e+09 | AY17: 7.1232191e+08 | AZ17: 0 | BA17: 0 | BB17: 2.9955896e+08 | BC17: 28187.83 | BD17: 0 | BE17: 0 | BF17: 0 | BG17: 0.47 | BH17: 28187.36 | BI17: 0 | BJ17: 0 | BK17: 0 | BL17: 1.8591636e+09 | BM17: 0 | BN17: 0 | BO17: 0 | BP17: 0 | BQ17: 0 | BR17: 0 | BS17: 0 | BT17: 0 | BU17: 0 | BV17: 0 | BW17: 0 | BX17: 0 | BY17: 0 | BZ17: 0 | CA17: 0 | CB17: 0 | CC17: 0 | CD17: 0 | CE17: 0 | CF17: 0 | CG17: 0 | CH17: 12091.52 | CI17: 0 | CJ17: 0 | CK17: 12091.52 | CL17: 0 | CM17: 0 | CN17: 0 | CO17: 0 | CP17: 1.6661083e+09 | CQ17: 63188816 | CR17: 1.6029195e+09 | CS17: 0 | CT17: 0 | CU17: 0 | CV17: 0 | CW17: 0 | CX17: 0 | CY17: 0 | CZ17: 0 | DA17: 30789211 | DB17: 0 | DC17: 0 | DD17: 0 | DE17: 0 | DF17: 18524326 | DG17: 19908087 | DH17: 15894448 | DI17: 72614698 | DJ17: -96152348 | DK17: 0 | DL17: 1.6225402e+08 | DM17: 2.5600842e+08 | DN17: 0 | DO17: 0 | DP17: 0 | DQ17: 0 | DR17: -93754406 | DS17: 0 | DT17: 0 | DU17: 0 | DV17: 0 | DW17: 0 | DX17: 0 | DY17: 0 | DZ17: 0 | EA17: 0 | EB17: 0 | EC17: 0 | ED17: 0 | EE17: 0 | EF17: 0
A18: VHV Allgemeine Sigorta AŞ | B18: 1013 | C18: HD | D18: 2.9195282e+09 | E18: 1.3214067e+09 | F18: 0 | G18: 0 | H18: 1.1968222e+09 | I18: 0 | J18: 1.2458446e+08 | K18: 0 | L18: 58102881 | M18: 0 | N18: 58102881 | O18: 0 | P18: 0 | Q18: 0 | R18: 0 | S18: 0 | T18: 0 | U18: 1.0738319e+09 | V18: 9.1935915e+08 | W18: -80339.38 | X18: 1.542531e+08 | Y18: 0 | Z18: 0 | AA18: 0 | AB18: 0 | AC18: 0 | AD18: 1.6373727e+08 | AE18: -1.6343727e+08 | AF18: 0 | AG18: 0 | AH18: 0 | AI18: 0 | AJ18: 0 | AK18: 0 | AL18: 0 | AM18: 0 | AN18: 0 | AO18: 0 | AP18: 0 | AQ18: 0 | AR18: 0 | AS18: 0 | AT18: 0 | AU18: 0 | AV18: 0 | AW18: 0 | AX18: 4.220398e+08 | AY18: 2.5109452e+08 | AZ18: 0 | BA18: 0 | BB18: 170945280 | BC18: 44146985 | BD18: 0 | BE18: 42588215 | BF18: 0 | BG18: 1558769.7 | BH18: 0 | BI18: 0 | BJ18: 0 | BK18: 0 | BL18: 1.4618596e+08 | BM18: 0 | BN18: 0 | BO18: 0 | BP18: 0 | BQ18: 0 | BR18: 0 | BS18: 0 | BT18: 0 | BU18: 0 | BV18: 0 | BW18: 0 | BX18: 0 | BY18: 0 | BZ18: 0 | CA18: 0 | CB18: 0 | CC18: 0 | CD18: 0 | CE18: 0 | CF18: 0 | CG18: 0 | CH18: 1962718.2 | CI18: 0 | CJ18: 0 | CK18: 1962718.2 | CL18: 0 | CM18: 0 | CN18: 0 | CO18: 0 | CP18: 0 | CQ18: 0 | CR18: 0 | CS18: 0 | CT18: 0 | CU18: 0 | CV18: 0 | CW18: 0 | CX18: 0 | CY18: 0 | CZ18: 0 | DA18: 50970302 | DB18: 0 | DC18: 0 | DD18: 0 | DE18: 3829213.7 | DF18: 4733921.6 | DG18: 0 | DH18: 35918654 | DI18: 65643282 | DJ18: -59154769 | DK18: 0 | DL18: 16335358 | DM18: 29969214 | DN18: 0 | DO18: 0 | DP18: 0 | DQ18: 0 | DR18: -13633857 | DS18: 0 | DT18: 0 | DU18: 0 | DV18: 0 | DW18: 0 | DX18: 76917586 | DY18: 0 | DZ18: 0 | EA18: 0 | EB18: 0 | EC18: 76917586 | ED18: 0 | EE18: 0 | EF18: 0
... A81: TOPLAM (HAYAT DIŞI ŞİRKETLER+HAYAT VE EMEKLİLİK ŞİRKETLERİ) | B81: 9003 | C81: T (HD+H+E) | D81: 2.2452939e+12 | E81: 5.850349e+11 | F81: 5585763.2 | G81: 35070126 | H81: 4.67103e+11 | I81: -6310.97 | J81: 1.148111e+11 | K81: 3.0801448e+09 | L81: 8.0241602e+11 | M81: 3.3222796e+11 | N81: 6.9567248e+10 | O81: 2.7089864e+11 | P81: 1.5446905e+09 | Q81: 0 | R81: 1.2818281e+11 | S81: 0 | T81: -5327818 | U81: 6.9324991e+11 | V81: 2.6208064e+11 | W81: -3.9173953e+09 | X81: 1.497758e+10 | Y81: -92718171 | Z81: 5.9348539e+09 | AA81: 4.6638748e+09 | AB81: 0 | AC81: 4.0940422e+11 | AD81: 2.8340856e+10 | AE81: -2.8142e+10 | AF81: 6.6700859e+08 | AG81: 47598423 | AH81: 2.2090569e+08 | AI81: 57216873 | AJ81: 39118576 | AK81: 19016184 | AL81: 2.8315285e+08 | AM81: 0 | AN81: 1551278.1 | AO81: -1551278.1 | AP81: 1.3845075e+10 | AQ81: 0 | AR81: 0 | AS81: 1.1825344e+09 | AT81: 1.3005343e+10 | AU81: -3.6865303e+08 | AV81: 1.1896889e+08 | AW81: -93118227 | AX81: 1.387912e+11 | AY81: 1.1937675e+11 | AZ81: 38277758 | BA81: 2.4898737e+09 | BB81: 1.6886298e+10 | BC81: 1.1289809e+10 | BD81: 1.0860152e+08 | BE81: 8.1286187e+09 | BF81: 0.05 | BG81: 2.559637e+09 | BH81: 3.2110338e+08 | BI81: 27311.27 | BJ81: 1.8945286e+08 | BK81: -17631484 | BL81: 2.1362742e+12 | BM81: 2.0030238e+12 | BN81: 6.329426e+08 | BO81: 0 | BP81: 0 | BQ81: 0 | BR81: 0 | BS81: 8.3885586e+08 | BT81: 0 | BU81: 2.0015519e+12 | BV81: 9.4534813e+08 | BW81: -9.4524307e+08 | BX81: 8044089.9 | BY81: 8044089.9 | BZ81: 0 | CA81: 0 | CB81: 0 | CC81: 0 | CD81: 0 | CE81: 0 | CF81: 0 | CG81: 0 | CH81: 6.8589789e+08 | CI81: 0 | CJ81: 0 | CK81: 6.8566989e+08 | CL81: 228000 | CM81: 0 | CN81: 1620487.7 | CO81: -1620487.7 | CP81: 5.9786746e+10 | CQ81: 3.6615823e+09 | CR81: 2.1916577e+10 | CS81: 0 | CT81: 3.4197652e+10 | CU81: -10000000 | CV81: 0 | CW81: 0 | CX81: 0 | CY81: 44753917 | CZ81: -23819127 | DA81: 3.08256e+10 | DB81: 1.1270205e+10 | DC81: -115493.53 | DD81: 8.0962363e+09 | DE81: 1.5778607e+09 | DF81: 4.8112597e+09 | DG81: 3.0542049e+09 | DH81: 2.3523325e+09 | DI81: 7.5371469e+09 | DJ81: -8.2885827e+09 | DK81: 4.1505224e+08 | DL81: 1.690734e+10 | DM81: 1.3608234e+10 | DN81: 4.9348298e+08 | DO81: 0 | DP81: 1.7508629e+09 | DQ81: 8.5299026e+09 | DR81: -1.053915e+10 | DS81: 3.0640075e+09 | DT81: 8.046542e+09 | DU81: 6.1365868e+09 | DV81: 0 | DW81: 1.9099553e+09 | DX81: 1.6990259e+10 | DY81: 0 | DZ81: 0 | EA81: 0 | EB81: 0 | EC81: 1.6858592e+10 | ED81: 1.316671e+08 | EE81: 0 | EF81: 0
A82: TOPLAM (HAYAT DIŞI ŞİRKETLER+HAYAT VE EMEKLİLİK ŞİRKETLERİ+REASÜRANS ŞİRKETLERİ) | C82: T (HD+H+E+R) | D82: 2.2452939e+12 | E82: 5.850349e+11 | F82: 5585763.2 | G82: 35070126 | H82: 4.67103e+11 | I82: -6310.97 | J82: 1.148111e+11 | K82: 3.0801448e+09 | L82: 8.0241602e+11 | M82: 3.3222796e+11 | N82: 6.9567248e+10 | O82: 2.7089864e+11 | P82: 1.5446905e+09 | Q82: 0 | R82: 1.2818281e+11 | S82: 0 | T82: -5327818 | U82: 6.9324991e+11 | V82: 2.6208064e+11 | W82: -3.9173953e+09 | X82: 1.497758e+10 | Y82: -92718171 | Z82: 5.9348539e+09 | AA82: 4.6638748e+09 | AB82: 0 | AC82: 4.0940422e+11 | AD82: 2.8340856e+10 | AE82: -2.8142e+10 | AF82: 6.6700859e+08 | AG82: 47598423 | AH82: 2.2090569e+08 | AI82: 57216873 | AJ82: 39118576 | AK82: 19016184 | AL82: 2.8315285e+08 | AM82: 0 | AN82: 1551278.1 | AO82: -1551278.1 | AP82: 1.3845075e+10 | AQ82: 0 | AR82: 0 | AS82: 1.1825344e+09 | AT82: 1.3005343e+10 | AU82: -3.6865303e+08 | AV82: 1.1896889e+08 | AW82: -93118227 | AX82: 1.387912e+11 | AY82: 1.1937675e+11 | AZ82: 38277758 | BA82: 2.4898737e+09 | BB82: 1.6886298e+10 | BC82: 1.1289809e+10 | BD82: 1.0860152e+08 | BE82: 8.1286187e+09 | BF82: 0.05 | BG82: 2.559637e+09 | BH82: 3.2110338e+08 | BI82: 27311.27 | BJ82: 1.8945286e+08 | BK82: -17631484 | BL82: 2.1362742e+12 | BM82: 2.0030238e+12 | BN82: 6.329426e+08 | BO82: 0 | BP82: 0 | BQ82: 0 | BR82: 0 | BS82: 8.3885586e+08 | BT82: 0 | BU82: 2.0015519e+12 | BV82: 9.4534813e+08 | BW82: -9.4524307e+08 | BX82: 8044089.9 | BY82: 8044089.9 | BZ82: 0 | CA82: 0 | CB82: 0 | CC82: 0 | CD82: 0 | CE82: 0 | CF82: 0 | CG82: 0 | CH82: 6.8589789e+08 | CI82: 0 | CJ82: 0 | CK82: 6.8566989e+08 | CL82: 228000 | CM82: 0 | CN82: 1620487.7 | CO82: -1620487.7 | CP82: 5.9786746e+10 | CQ82: 3.6615823e+09 | CR82: 2.1916577e+10 | CS82: 0 | CT82: 3.4197652e+10 | CU82: -10000000 | CV82: 0 | CW82: 0 | CX82: 0 | CY82: 44753917 | CZ82: -23819127 | DA82: 3.08256e+10 | DB82: 1.1270205e+10 | DC82: -115493.53 | DD82: 8.0962363e+09 | DE82: 1.5778607e+09 | DF82: 4.8112597e+09 | DG82: 3.0542049e+09 | DH82: 2.3523325e+09 | DI82: 7.5371469e+09 | DJ82: -8.2885827e+09 | DK82: 4.1505224e+08 | DL82: 1.690734e+10 | DM82: 1.3608234e+10 | DN82: 4.9348298e+08 | DO82: 0 | DP82: 1.7508629e+09 | DQ82: 8.5299026e+09 | DR82: -1.053915e+10 | DS82: 3.0640075e+09 | DT82: 8.046542e+09 | DU82: 6.1365868e+09 | DV82: 0 | DW82: 1.9099553e+09 | DX82: 1.6990259e+10 | DY82: 0 | DZ82: 0 | EA82: 0 | EB82: 0 | EC82: 1.6858592e+10 | ED82: 1.316671e+08 | EE82: 0 | EF82: 0

Sheet Aktif Ozet
A1: BİLANÇO
A2: Aktif Ozet
A3: 01.01.2026-30.06.2026
D5: 1 | E5: 10 | F5: 11 | G5: 12 | H5: 13 | I5: 14 | J5: 18 | K5: 19 | L5: 2 | M5: 22 | N5: 23 | O5: 24 | P5: 25 | Q5: 26 | R5: 27 | S5: 28 | T5: 29
A6: Şirket Adı | B6: Şirket Kodu | C6: Şirket Tipi | D6: Cari Varlıklar | E6: Nakit ve Nakit Benzeri Varlıklar | F6: Finansal Varlıklar ile Riski Sigortalılara Ait Finansal Yatırımlar | G6: Esas Faaliyetlerden Alacaklar | H6: İlişkili Taraflardan Alacaklar | I6: Diğer Alacaklar | J6: Gelecek Aylara Ait Giderler ve Gelir Tahakkukları | K6: Diğer Cari Varlıklar | L6: Cari Olmayan Varlıklar | M6: Esas Faaliyetlerden Alacaklar | N6: İlişkili Taraflardan Alacaklar | O6: Diğer Alacaklar | P6: Finansal Varlıklar | Q6: Maddi Varlıklar | R6: Maddi Olmayan Varlıklar | S6: Gelecek Yıllara Ait Giderler ve Gelir Tahakkukları | T6: Diğer Cari Olmayan Varlıklar
A7: Chubb European Group SE Merkezi Fransa Türkiye İstanbul Şubesi | B7: 1001 | C7: HD | D7: 4.3957879e+09 | E7: 2.3519865e+09 | F7: 0 | G7: 1.7422527e+09 | H7: 0 | I7: 10753225 | J7: 2.0141114e+08 | K7: 89384376 | L7: 1.3623502e+08 | M7: 0 | N7: 0 | O7: 0 | P7: 0 | Q7: 79172978 | R7: 9733.4 | S7: 0 | T7: 57052309
A8: Aksigorta AŞ | B8: 1003 | C8: HD | D8: 3.7466004e+10 | E8: 1.194898e+10 | F8: 1.3858727e+10 | G8: 6.1730148e+09 | H8: 0 | I8: 58302555 | J8: 5.1047353e+09 | K8: 3.2224377e+08 | L8: 2.6478346e+09 | M8: 0 | N8: 0 | O8: 0 | P8: 17094836 | Q8: 6.0430624e+08 | R8: 1.171667e+09 | S8: 17851674 | T8: 8.3691486e+08
A9: Allianz Sigorta AŞ | B9: 1004 | C9: HD | D9: 1.7252027e+11 | E9: 8.246623e+10 | F9: 4.0861727e+10 | G9: 3.5078144e+10 | H9: 74167207 | I9: 1.7698081e+08 | J9: 1.218222e+10 | K9: 1.6807961e+09 | L9: 2.3990428e+10 | M9: 0 | N9: 0 | O9: 385529.71 | P9: 1.8436745e+10 | Q9: 2.1631854e+09 | R9: 1.3602913e+09 | S9: 63102545 | T9: 1.9667177e+09
A10: Anadolu Anonim Türk Sigorta Şirketi | B10: 1005 | C10: HD | D10: 1.3950934e+11 | E10: 3.8872587e+10 | F10: 6.0995842e+10 | G10: 2.7211597e+10 | H10: 0 | I10: 8.779279e+08 | J10: 1.0480458e+10 | K10: 1.0709242e+09 | L10: 1.1824725e+10 | M10: 0 | N10: 0 | O10: 552554.61 | P10: 8849400000 | Q10: 1.5148686e+09 | R10: 1.0918173e+09 | S10: 1.047453e+08 | T10: 263340929
A11: Ankara Anonim Türk Sigorta Şirketi | B11: 1006 | C11: HD | D11: 2.786742e+10 | E11: 1.7205316e+10 | F11: 6.1452956e+09 | G11: 2.5346077e+09 | H11: 2186171.2 | I11: 1672585 | J11: 1.4523094e+09 | K11: 5.2603231e+08 | L11: 1.9246251e+09 | M11: 0 | N11: 0 | O11: 189769.37 | P11: 29757356 | Q11: 1.3543795e+09 | R11: 14514675 | S11: 0 | T11: 5.2578379e+08
A12: Atradius Crédito y Caución S.A. de Seguros y Reaseguros, İstanbul Şubesi | B12: 1007 | C12: HD | D12: 1.4992056e+09 | E12: 7.9451428e+08 | F12: 0 | G12: 5.910541e+08 | H12: 16309056 | I12: 28963.25 | J12: 77429480 | K12: 19869727 | L12: 1.9353974e+08 | M12: 61831792 | N12: 8044089.9 | O12: 0 | P12: 0 | Q12: 22478008 | R12: 0 | S12: 12863584 | T12: 88322267
A13: Unico Sigorta AŞ | B13: 1008 | C13: HD | D13: 2.8194336e+10 | E13: 1.3201421e+10 | F13: 8.6439142e+09 | G13: 2.9193832e+09 | H13: 0 | I13: 60303342 | J13: 2.5457683e+09 | K13: 8.2354528e+08 | L13: 4.6477041e+09 | M13: 0 | N13: 0 | O13: 50000 | P13: 16651655 | Q13: 4.1254977e+09 | R13: 2.9295378e+08 | S13: 0 | T13: 2.1255097e+08
A14: Axa Sigorta AŞ | B14: 1009 | C14: HD | D14: 1.3150271e+11 | E14: 3.1841853e+10 | F14: 54882147208 | G14: 2.9988149e+10 | H14: 348425.38 | I14: 1.3003083e+09 | J14: 1.3052836e+10 | K14: 4.3706622e+08 | L14: 2.7048193e+09 | M14: 0 | N14: 0 | O14: 0 | P14: 17262968 | Q14: 1.1779791e+09 | R14: 1.061127e+09 | S14: 0 | T14: 4.4845023e+08
A15: BNP Paribas Cardif Sigorta AŞ | B15: 1010 | C15: HD | D15: 7.8883816e+09 | E15: 3.3896503e+09 | F15: 3.2850177e+09 | G15: 4.6276257e+08 | H15: 0 | I15: 0 | J15: 7.5097189e+08 | K15: -20763.79 | L15: 5.5106083e+09 | M15: 0 | N15: 0 | O15: 0 | P15: 0 | Q15: 23339282 | R15: 94570717 | S15: 5.3589169e+09 | T15: 33781425
A16: Coface Sigorta AŞ | B16: 1011 | C16: HD | D16: 1.7614077e+09 | E16: 6.6890541e+08 | F16: 0 | G16: 8.7057473e+08 | H16: 7612486.9 | I16: 4001411.1 | J16: 1.9420005e+08 | K16: 16113578 | L16: 3.5594331e+08 | M16: 175585203 | N16: 0 | O16: 0 | P16: 0 | Q16: 28790565 | R16: 6255841.2 | S16: 36944153 | T16: 108367548
A17: Corpus Sigorta AŞ | B17: 1012 | C17: HD | D17: 1.759045e+10 | E17: 9.7434663e+09 | F17: 5.0267871e+09 | G17: 1.772391e+09 | H17: 0 | I17: 35897023 | J17: 1.0118809e+09 | K17: 28187.83 | L17: 1.8591636e+09 | M17: 0 | N17: 0 | O17: 12091.52 | P17: 1.6661083e+09 | Q17: 30789211 | R17: 1.6225402e+08 | S17: 0 | T17: 0
A18: VHV Allgemeine Sigorta AŞ | B18: 1013 | C18: HD | D18: 2.9195282e+09 | E18: 1.3214067e+09 | F18: 58102881 | G18: 1.0738319e+09 | H18: 0 | I18: 0 | J18: 4.220398e+08 | K18: 44146985 | L18: 1.4618596e+08 | M18: 0 | N18: 0 | O18: 1962718.2 | P18: 0 | Q18: 50970302 | R18: 16335358 | S18: 0 | T18: 76917586
... A81: TOPLAM (HAYAT DIŞI ŞİRKETLER+HAYAT VE EMEKLİLİK ŞİRKETLERİ) | B81: 9003 | C81: T (HD+H+E) | D81: 2.2452939e+12 | E81: 5.850349e+11 | F81: 8.0241602e+11 | G81: 6.9324991e+11 | H81: 6.6700859e+08 | I81: 1.3845075e+10 | J81: 1.387912e+11 | K81: 1.1289809e+10 | L81: 2.1362742e+12 | M81: 2.0030238e+12 | N81: 8044089.9 | O81: 6.8589789e+08 | P81: 5.9786746e+10 | Q81: 3.08256e+10 | R81: 1.690734e+10 | S81: 8.046542e+09 | T81: 1.6990259e+10
A82: TOPLAM (HAYAT DIŞI ŞİRKETLER+HAYAT VE EMEKLİLİK ŞİRKETLERİ+REASÜRANS ŞİRKETLERİ) | C82: T (HD+H+E+R) | D82: 2.2452939e+12 | E82: 5.850349e+11 | F82: 8.0241602e+11 | G82: 6.9324991e+11 | H82: 6.6700859e+08 | I82: 1.3845075e+10 | J82: 1.387912e+11 | K82: 1.1289809e+10 | L82: 2.1362742e+12 | M82: 2.0030238e+12 | N82: 8044089.9 | O82: 6.8589789e+08 | P82: 5.9786746e+10 | Q82: 3.08256e+10 | R82: 1.690734e+10 | S82: 8.046542e+09 | T82: 1.6990259e+10

Sheet Pasif Detay
A1: BİLANÇO
A2: Pasif Detay
A3: 01.01.2026-30.06.2026
